Workbook
Name Ghi_chú_PABT: #REF!
Name Hạng_mục_chi: Table11[Hạng mục chi]
Name Hạng_mục_chi: Table11[Hạng mục chi]
Name Hạng_mục_chi: Table11[Hạng mục chi]
Name Hạng_mục_chi: Table11[Hạng mục chi]
Name Hình_thức_thu_chi: Table2[[#All],[Hình thức thu chi]]
Name Hình_thức_thu_chi: Table2[[#All],[Hình thức thu chi]]
Name Hình_thức_thu_chi: Table2[[#All],[Hình thức thu chi]]
Name Hình_thức_thu_chi: Table2[[#All],[Hình thức thu chi]]
Name Loại_chứng_từ: Table1[[#All],[Loại chứng từ]]
Name Loại_chứng_từ: Table1[[#All],[Loại chứng từ]]
Name Loại_chứng_từ: Table1[[#All],[Loại chứng từ]]
Name Loại_chứng_từ: Table1[[#All],[Loại chứng từ]]
Name Số_QĐ_CV_chi_phí_hội_đồng: Table9[[#All],[Số QĐ/CV chi phí hội đồng]]
Name Số_QĐ_CV_chi_phí_hội_đồng: Table9[[#All],[Số QĐ/CV chi phí hội đồng]]
Name Số_QĐ_CV_chi_phí_hội_đồng: Table9[[#All],[Số QĐ/CV chi phí hội đồng]]
Name Số_QĐ_CV_chi_phí_hội_đồng: Table9[[#All],[Số QĐ/CV chi phí hội đồng]]
Name Số_QĐ_phương_án_bồi_thường_gốc: Table6[[#All],[Số QĐ bồi thường gốc]]
Name Số_QĐ_phương_án_bồi_thường_gốc: Table6[[#All],[Số QĐ bồi thường gốc]]
Name Số_QĐ_phương_án_bồi_thường_gốc: Table6[[#All],[Số QĐ bồi thường gốc]]
Name Số_QĐ_phương_án_bồi_thường_gốc: Table6[[#All],[Số QĐ bồi thường gốc]]
Name Số_QĐ_thu_hồi_đất_gốc: Table7[[#All],[Số QĐ thu hồi đất gốc]]
Name Số_QĐ_thu_hồi_đất_gốc: Table7[[#All],[Số QĐ thu hồi đất gốc]]
Name Số_QĐ_thu_hồi_đất_gốc: Table7[[#All],[Số QĐ thu hồi đất gốc]]
Name Số_QĐ_thu_hồi_đất_gốc: Table7[[#All],[Số QĐ thu hồi đất gốc]]
Name Số_QĐ_thưởng_GPMB_nhanh_gốc: Table8[[#All],[Số QĐ thưởng GPMB nhanh gốc]]
Name Số_QĐ_thưởng_GPMB_nhanh_gốc: Table8[[#All],[Số QĐ thưởng GPMB nhanh gốc]]
Name Số_QĐ_thưởng_GPMB_nhanh_gốc: Table8[[#All],[Số QĐ thưởng GPMB nhanh gốc]]
Name Số_QĐ_thưởng_GPMB_nhanh_gốc: Table8[[#All],[Số QĐ thưởng GPMB nhanh gốc]]

Sheet DM thu chi
A10: Loại chứng từ | C10: Hình thức thu chi | E10: Hạng mục chi
A11: Phiếu chi | C11: Tiền mặt | E11: Chi ngoài PABT
A12: Phiếu thu | C12: Chuyển khoản | E12: Chi ngoài GPMB nhanh
C13: Tạm ứng tiền mặt | E13: Bồi thường thiệt hại do thi công
C14: Tạm ứng chuyển khoản | E14: Hỗ trợ di chuyển mồ mả
E15: Hỗ trợ thuê nhà
E16: Bồi thường giải phóng mặt bằng
E17: Thưởng GPMB nhanh
A20: BT_DM_LoaiChungTu | C20: BT_DM_HTThuChi | E20: BT_DM_HMThuChi
A21: LoaiChungTu | C21: HinhThucthuChi | E21: HangMucChi

Sheet DM đối tượng PABT
A1: CÔNG TY CỔ PHẦN XÂY DỰNG ĐỨC ANH
A2: KHU CÔNG NGHIỆP CẨM KHÊ
A4: DANH MỤC ĐỐI TƯỢNG THEO PHƯƠNG ÁN BỒI THƯỜNG
A5: BT_DM_DTTPANBT
B6: Id_DM_QDBoiThuongGoc | C6: Id_ThongTinChuHo
A7: STT | B7: Số QĐ bồi thường gốc | C7: Họ và tên chủ hộ | D7: Xã/phường | E7: Khu/thôn | F7: CMT/CCCD
A8: 1 | B8: {=_xlfn.UNIQUE(_xlfn.SORTBY(_xlfn.HSTACK('4. C.Tiết P.Án B.Thường'!$B$11:$B$19954,'4. C.Tiết P.Án B.Thường'!$J$11:$M$19954),'4. C.Tiết P.Án B.Thường'!$B$11:$B$19954,1,'4. C.Tiết P.Án B.Thường'!$J$11:$J$19954,1,'4. C.Tiết P.Án B.Thường'!$K$11:$K$19954,1,'4. C.Tiết P.Án B.Thường'!$L$11:$L$19954,1,'4. C.Tiết P.Án B.Thường'!$M$11:$M$19954,1))} -> 110 | C8: Nguyễn Đức Anh | D8: Tiên Cát | E8: Minh Hà | F8: 123A
A9: 2 | B9: 120 | C9: Nguyễn Đức Anh | D9: Tiên Cát | E9: Minh Hà | F9: 123A
A10: 3 | B10: 130 | C10: Nguyễn Đức Anh | D10: Tiên Cát | E10: Minh Hà | F10: 123A
A11: 4 | B11: 140 | C11: Nguyễn Đức Anh | D11: Tiên Cát | E11: Minh Hà | F11: 123A
A12: 5 | B12: Tạm ứng | C12: Nguyễn Đức Anh | D12: Tiên Cát | E12: Minh Hà | F12: 123A
A13: 6 | B13: 0 | C13: 0 | D13: 0 | E13: 0 | F13: 0
A14: 7
A15: 8
A16: 9
A17: 10
A18: 11
A19: 12
A20: 13
A21: 14
A22: 15
A23: 16
A24: 17
A25: 18
... A54: 47

Sheet DM Đối tượng GPMB nhanh
A1: CÔNG TY CỔ PHẦN XÂY DỰNG ĐỨC ANH
A2: KHU CÔNG NGHIỆP CẨM KHÊ
A4: DANH MỤC ĐỐI TƯỢNG THEO SỐ QUYẾT ĐỊNH THƯỞNG GIẢI PHÓNG MẶT BẰNG NHANH
A6: BT_DM_DTTSQDThuongGPMB
B7: Id_QDPABTKHopGPMBNhanh | C7: Id_ThongTinChuHo
A8: STT | B8: Số QĐ GPMB nhanh gốc | C8: Họ và tên chủ hộ | D8: Xã/phường | E8: Khu/thôn | F8: CMT/CCCD
B9: {=_xlfn.UNIQUE(_xlfn.SORTBY(_xlfn.HSTACK(_xlfn._xlws.FILTER('4. C.Tiết P.Án B.Thường'!$F$11:$F$19950,'4. C.Tiết P.Án B.Thường'!$F$11:$F$19950<>""),_xlfn._xlws.FILTER('4. C.Tiết P.Án B.Thường'!$J$11:$J$19950,'4. C.Tiết P.Án B.Thường'!$F$11:$F$19950<>""),_xlfn._xlws.FILTER('4. C.Tiết P.Án B.Thường'!$K$11:$K$19950,'4. C.Tiết P.Án B.Thường'!$F$11:$F$19950<>""),_xlfn._xlws.FILTER('4. C.Tiết P.Án B.Thường'!$L$11:$L$19950,'4. C.Tiết P.Án B.Thường'!$F$11:$F$19950<>""),_xlfn._xlws.FILTER('4. C.Tiết P.Án B.Thường'!$M$11:$M$19950,'4. C.Tiết P.Án B.Thường'!$F$11:$F$19950<>"")),_xlfn._xlws.FILTER('4. C.Tiết P.Án B.Thường'!$F$11:$F$19950,'4. C.Tiết P.Án B.Thường'!$F$11:$F$19950<>""),1,_xlfn._xlws.FILTER('4. C.Tiết P.Án B.Thường'!$J$11:$J$19950,'4. C.Tiết P.Án B.Thường'!$F$11:$F$19950<>""),1,_xlfn._xlws.FILTER('4. C.Tiết P.Án B.Thường'!$K$11:$K$19950,'4. C.Tiết P.Án B.Thường'!$F$11:$F$19950<>""),1,_xlfn._xlws.FILTER('4. C.Tiết P.Án B.Thường'!$L$11:$L$19950,'4. C.Tiết P.Án B.Thường'!$F$11:$F$19950<>""),1,_xlfn._xlws.FILTER('4. C.Tiết P.Án B.Thường'!$M$11:$M$19950,'4. C.Tiết P.Án B.Thường'!$F$11:$F$19950<>""),1))} -> 220 | C9: Nguyễn Đức Anh | D9: Tiên Cát | E9: Minh Hà | F9: 123A
B10: 230 | C10: Nguyễn Đức Anh | D10: Tiên Cát | E10: Minh Hà | F10: 123A
B11: 240 | C11: Nguyễn Đức Anh | D11: Tiên Cát | E11: Minh Hà | F11: 123A
B12: Tạm ứng | C12: Nguyễn Đức Anh | D12: Tiên Cát | E12: Minh Hà | F12: 123A

Sheet 1. QĐ PABT K.hợp GPMB nhanh
A1: CÔNG TY CỔ PHẦN XÂY DỰNG ĐỨC ANH
A2: KHU CÔNG NGHIỆP CẨM KHÊ
A4: BẢNG KẾT HỢP QUYẾT ĐỊNH BỒI THƯỜNG GỐC VÀ QUYẾT ĐỊNH GIẢI PHÓNG MẶT BẰNG NHANH GỐC
F5: BT_QDPABTKHopGPMBNhanh
A6: STT | B6: Số quyết định bồi thường gốc | C6: N/T/N QĐ bồi thường gốc | D6: QĐ thưởng GPMB nhanh gốc | E6: N/T/N QĐ thưởng GPMB nhanh gốc | F6: Id_DM_QDBoiThuongGoc | G6: Id_DM_QDTGPMBNhanhGoc
B7: 100 | C7: =IF(B7<>"",INDEX(Table6[N/T/N PABT gốc],MATCH(B7,Table6[Số QĐ bồi thường gốc],0)),"") -> 45296 | D7: 200 | E7: =IF(D7<>"",INDEX(Table8[N/T/N GPMB nhanh gốc],MATCH(D7,Table8[Số QĐ thưởng GPMB nhanh gốc],0)),"") -> 45301
B8: 110 | C8: =IF(B8<>"",INDEX(Table6[N/T/N PABT gốc],MATCH(B8,Table6[Số QĐ bồi thường gốc],0)),"") -> 45327 | D8: Tạm ứng | E8: =IF(D8<>"",INDEX(Table8[N/T/N GPMB nhanh gốc],MATCH(D8,Table8[Số QĐ thưởng GPMB nhanh gốc],0)),"") -> 0
B9: 110 | C9: =IF(B9<>"",INDEX(Table6[N/T/N PABT gốc],MATCH(B9,Table6[Số QĐ bồi thường gốc],0)),"") -> 45327 | D9: 210 | E9: =IF(D9<>"",INDEX(Table8[N/T/N GPMB nhanh gốc],MATCH(D9,Table8[Số QĐ thưởng GPMB nhanh gốc],0)),"") -> 45337
B10: 120 | C10: =IF(B10<>"",INDEX(Table6[N/T/N PABT gốc],MATCH(B10,Table6[Số QĐ bồi thường gốc],0)),"") -> 45356 | D10: 220 | E10: =IF(D10<>"",INDEX(Table8[N/T/N GPMB nhanh gốc],MATCH(D10,Table8[Số QĐ thưởng GPMB nhanh gốc],0)),"") -> 45361
B11: 130 | C11: =IF(B11<>"",INDEX(Table6[N/T/N PABT gốc],MATCH(B11,Table6[Số QĐ bồi thường gốc],0)),"") -> 45387 | D11: 230 | E11: =IF(D11<>"",INDEX(Table8[N/T/N GPMB nhanh gốc],MATCH(D11,Table8[Số QĐ thưởng GPMB nhanh gốc],0)),"") -> 45392
B12: 140 | C12: =IF(B12<>"",INDEX(Table6[N/T/N PABT gốc],MATCH(B12,Table6[Số QĐ bồi thường gốc],0)),"") -> 45417 | D12: 240 | E12: =IF(D12<>"",INDEX(Table8[N/T/N GPMB nhanh gốc],MATCH(D12,Table8[Số QĐ thưởng GPMB nhanh gốc],0)),"") -> 45422
C13: =IF(B13<>"",INDEX(Table6[N/T/N PABT gốc],MATCH(B13,Table6[Số QĐ bồi thường gốc],0)),"") | E13: =IF(D13<>"",INDEX(Table8[N/T/N GPMB nhanh gốc],MATCH(D13,Table8[Số QĐ thưởng GPMB nhanh gốc],0)),"")
C14: =IF(B14<>"",INDEX(Table6[N/T/N PABT gốc],MATCH(B14,Table6[Số QĐ bồi thường gốc],0)),"") | E14: =IF(D14<>"",INDEX(Table8[N/T/N GPMB nhanh gốc],MATCH(D14,Table8[Số QĐ thưởng GPMB nhanh gốc],0)),"")
C15: =IF(B15<>"",INDEX(Table6[N/T/N PABT gốc],MATCH(B15,Table6[Số QĐ bồi thường gốc],0)),"") | E15: =IF(D15<>"",INDEX(Table8[N/T/N GPMB nhanh gốc],MATCH(D15,Table8[Số QĐ thưởng GPMB nhanh gốc],0)),"")
C16: =IF(B16<>"",INDEX(Table6[N/T/N PABT gốc],MATCH(B16,Table6[Số QĐ bồi thường gốc],0)),"") | E16: =IF(D16<>"",INDEX(Table8[N/T/N GPMB nhanh gốc],MATCH(D16,Table8[Số QĐ thưởng GPMB nhanh gốc],0)),"")
C17: =IF(B17<>"",INDEX(Table6[N/T/N PABT gốc],MATCH(B17,Table6[Số QĐ bồi thường gốc],0)),"") | E17: =IF(D17<>"",INDEX(Table8[N/T/N GPMB nhanh gốc],MATCH(D17,Table8[Số QĐ thưởng GPMB nhanh gốc],0)),"")
C18: =IF(B18<>"",INDEX(Table6[N/T/N PABT gốc],MATCH(B18,Table6[Số QĐ bồi thường gốc],0)),"") | E18: =IF(D18<>"",INDEX(Table8[N/T/N GPMB nhanh gốc],MATCH(D18,Table8[Số QĐ thưởng GPMB nhanh gốc],0)),"")
C19: =IF(B19<>"",INDEX(Table6[N/T/N PABT gốc],MATCH(B19,Table6[Số QĐ bồi thường gốc],0)),"") | E19: =IF(D19<>"",INDEX(Table8[N/T/N GPMB nhanh gốc],MATCH(D19,Table8[Số QĐ thưởng GPMB nhanh gốc],0)),"")
C20: =IF(B20<>"",INDEX(Table6[N/T/N PABT gốc],MATCH(B20,Table6[Số QĐ bồi thường gốc],0)),"") | E20: =IF(D20<>"",INDEX(Table8[N/T/N GPMB nhanh gốc],MATCH(D20,Table8[Số QĐ thưởng GPMB nhanh gốc],0)),"")
C21: =IF(B21<>"",INDEX(Table6[N/T/N PABT gốc],MATCH(B21,Table6[Số QĐ bồi thường gốc],0)),"") | E21: =IF(D21<>"",INDEX(Table8[N/T/N GPMB nhanh gốc],MATCH(D21,Table8[Số QĐ thưởng GPMB nhanh gốc],0)),"")
C22: =IF(B22<>"",INDEX(Table6[N/T/N PABT gốc],MATCH(B22,Table6[Số QĐ bồi thường gốc],0)),"") | E22: =IF(D22<>"",INDEX(Table8[N/T/N GPMB nhanh gốc],MATCH(D22,Table8[Số QĐ thưởng GPMB nhanh gốc],0)),"")
C23: =IF(B23<>"",INDEX(Table6[N/T/N PABT gốc],MATCH(B23,Table6[Số QĐ bồi thường gốc],0)),"") | E23: =IF(D23<>"",INDEX(Table8[N/T/N GPMB nhanh gốc],MATCH(D23,Table8[Số QĐ thưởng GPMB nhanh gốc],0)),"")

Sheet 1.1 QĐ PABT K.Hợp T.Hồi đất
A1: CÔNG TY CỔ PHẦN XÂY DỰNG ĐỨC ANH
A2: KHU CÔNG NGHIỆP CẨM KHÊ
A4: BẢNG KẾT HỢP QUYẾT ĐỊNH QUYẾT ĐỊNH PHƯƠNG ÁN BỒI THƯỜNG GỐC VÀ QUYẾT ĐỊNH THU HỒI ĐẤT GỐC
F5: BT_QDPABTKHopTHoiDat
A6: STT | B6: Quyết định thu hồi đất gốc | C6: N/T/N QĐ thu hồi đất gốc | D6: Quyết định PABT gốc | E6: N/T/N QĐ phê duyệt PABT gốc | F6: Id_DM_QDThuhoiDatGoc | G6: Id_DM_QDCVChiPhiHoiDong
C7: =IF(B7<>"",INDEX(Table6[N/T/N PABT gốc],MATCH(B7,Table6[Số QĐ bồi thường gốc],0)),"") | E7: =IF(D7<>"",INDEX(Table7[N/T/N],MATCH(D7,Table7[Số QĐ thu hồi đất gốc],0)),"")
C8: =IF(B8<>"",INDEX(Table6[N/T/N PABT gốc],MATCH(B8,Table6[Số QĐ bồi thường gốc],0)),"") | E8: =IF(D8<>"",INDEX(Table7[N/T/N],MATCH(D8,Table7[Số QĐ thu hồi đất gốc],0)),"")
C9: =IF(B9<>"",INDEX(Table6[N/T/N PABT gốc],MATCH(B9,Table6[Số QĐ bồi thường gốc],0)),"") | E9: =IF(D9<>"",INDEX(Table7[N/T/N],MATCH(D9,Table7[Số QĐ thu hồi đất gốc],0)),"")
C10: =IF(B10<>"",INDEX(Table6[N/T/N PABT gốc],MATCH(B10,Table6[Số QĐ bồi thường gốc],0)),"") | E10: =IF(D10<>"",INDEX(Table7[N/T/N],MATCH(D10,Table7[Số QĐ thu hồi đất gốc],0)),"")
C11: =IF(B11<>"",INDEX(Table6[N/T/N PABT gốc],MATCH(B11,Table6[Số QĐ bồi thường gốc],0)),"") | E11: =IF(D11<>"",INDEX(Table7[N/T/N],MATCH(D11,Table7[Số QĐ thu hồi đất gốc],0)),"")
C12: =IF(B12<>"",INDEX(Table6[N/T/N PABT gốc],MATCH(B12,Table6[Số QĐ bồi thường gốc],0)),"") | E12: =IF(D12<>"",INDEX(Table7[N/T/N],MATCH(D12,Table7[Số QĐ thu hồi đất gốc],0)),"")
C13: =IF(B13<>"",INDEX(Table6[N/T/N PABT gốc],MATCH(B13,Table6[Số QĐ bồi thường gốc],0)),"") | E13: =IF(D13<>"",INDEX(Table7[N/T/N],MATCH(D13,Table7[Số QĐ thu hồi đất gốc],0)),"")
C14: =IF(B14<>"",INDEX(Table6[N/T/N PABT gốc],MATCH(B14,Table6[Số QĐ bồi thường gốc],0)),"") | E14: =IF(D14<>"",INDEX(Table7[N/T/N],MATCH(D14,Table7[Số QĐ thu hồi đất gốc],0)),"")
C15: =IF(B15<>"",INDEX(Table6[N/T/N PABT gốc],MATCH(B15,Table6[Số QĐ bồi thường gốc],0)),"") | E15: =IF(D15<>"",INDEX(Table7[N/T/N],MATCH(D15,Table7[Số QĐ thu hồi đất gốc],0)),"")
C16: =IF(B16<>"",INDEX(Table6[N/T/N PABT gốc],MATCH(B16,Table6[Số QĐ bồi thường gốc],0)),"") | E16: =IF(D16<>"",INDEX(Table7[N/T/N],MATCH(D16,Table7[Số QĐ thu hồi đất gốc],0)),"")
C17: =IF(B17<>"",INDEX(Table6[N/T/N PABT gốc],MATCH(B17,Table6[Số QĐ bồi thường gốc],0)),"") | E17: =IF(D17<>"",INDEX(Table7[N/T/N],MATCH(D17,Table7[Số QĐ thu hồi đất gốc],0)),"")
C18: =IF(B18<>"",INDEX(Table6[N/T/N PABT gốc],MATCH(B18,Table6[Số QĐ bồi thường gốc],0)),"") | E18: =IF(D18<>"",INDEX(Table7[N/T/N],MATCH(D18,Table7[Số QĐ thu hồi đất gốc],0)),"")

Sheet 2. QĐ PABT Đ.Chỉnh
A1: CÔNG TY CỔ PHẦN XÂY DỰNG ĐỨC ANH
A2: KHU CÔNG NGHIỆP CẨM KHÊ
A4: BẢNG THEO DÕI CÁC QUYẾT ĐỊNH BỒI THƯỜNG ĐIỀU CHỈNH THEO QUYẾT ĐỊNH BỒI THƯỜNG GỐC
F5: BT_QDPABTDChinh
A6: STT | B6: Số QĐ bồi thường gốc | C6: N/T/N bồi thường gốc | D6: Số QĐ bồi thường điều chỉnh | E6: N/T/N bồi thường điều chỉnh | F6: Id_DM_QDBoiThuongGoc | G6: SoQDBTDieuChinh | H6: NTNBTDieuChinh
A7: 1 | B7: 100 | C7: =IF(B7<>"",INDEX(Table6[N/T/N PABT gốc],MATCH(B7,Table6[Số QĐ bồi thường gốc],0)),"") -> 45296 | D7: Tạm ứng
A8: 2 | B8: 100 | C8: =IF(B8<>"",INDEX(Table6[N/T/N PABT gốc],MATCH(B8,Table6[Số QĐ bồi thường gốc],0)),"") -> 45296 | D8: 101 | E8: 45301
A9: 3 | B9: 110 | C9: =IF(B9<>"",INDEX(Table6[N/T/N PABT gốc],MATCH(B9,Table6[Số QĐ bồi thường gốc],0)),"") -> 45327 | D9: Tạm ứng
A10: 4 | B10: 110 | C10: =IF(B10<>"",INDEX(Table6[N/T/N PABT gốc],MATCH(B10,Table6[Số QĐ bồi thường gốc],0)),"") -> 45327 | D10: 111 | E10: 45332
A11: 5 | B11: 120 | C11: =IF(B11<>"",INDEX(Table6[N/T/N PABT gốc],MATCH(B11,Table6[Số QĐ bồi thường gốc],0)),"") -> 45356 | D11: Tạm ứng
A12: 6 | B12: 120 | C12: =IF(B12<>"",INDEX(Table6[N/T/N PABT gốc],MATCH(B12,Table6[Số QĐ bồi thường gốc],0)),"") -> 45356 | D12: 121 | E12: 45361
A13: 7 | B13: 130 | C13: =IF(B13<>"",INDEX(Table6[N/T/N PABT gốc],MATCH(B13,Table6[Số QĐ bồi thường gốc],0)),"") -> 45387 | D13: Tạm ứng
A14: 8 | B14: 130 | C14: =IF(B14<>"",INDEX(Table6[N/T/N PABT gốc],MATCH(B14,Table6[Số QĐ bồi thường gốc],0)),"") -> 45387 | D14: 131 | E14: 45392
A15: 9 | B15: 130 | C15: =IF(B15<>"",INDEX(Table6[N/T/N PABT gốc],MATCH(B15,Table6[Số QĐ bồi thường gốc],0)),"") -> 45387 | D15: 132 | E15: 45397
A16: 10 | B16: 140 | C16: =IF(B16<>"",INDEX(Table6[N/T/N PABT gốc],MATCH(B16,Table6[Số QĐ bồi thường gốc],0)),"") -> 45417 | D16: 141 | E16: 45427
A17: 11 | C17: =IF(B17<>"",INDEX(Table6[N/T/N PABT gốc],MATCH(B17,Table6[Số QĐ bồi thường gốc],0)),"")
A18: 12 | C18: =IF(B18<>"",INDEX(Table6[N/T/N PABT gốc],MATCH(B18,Table6[Số QĐ bồi thường gốc],0)),"")
A19: 13 | C19: =IF(B19<>"",INDEX(Table6[N/T/N PABT gốc],MATCH(B19,Table6[Số QĐ bồi thường gốc],0)),"")
A20: 14 | C20: =IF(B20<>"",INDEX(Table6[N/T/N PABT gốc],MATCH(B20,Table6[Số QĐ bồi thường gốc],0)),"")
A21: 15 | C21: =IF(B21<>"",INDEX(Table6[N/T/N PABT gốc],MATCH(B21,Table6[Số QĐ bồi thường gốc],0)),"")

Sheet 2.1 QĐ GPMB nhanh Đ.Chỉnh
A1: CÔNG TY CỔ PHẦN XÂY DỰNG ĐỨC ANH
A2: KHU CÔNG NGHIỆP CẨM KHÊ
A4: BẢNG THEO DÕI CÁC QUYẾT ĐỊNH GIẢI PHÓNG MẶT BẰNG NHANH ĐIỀU CHỈNH THEO QUYẾT ĐỊNH GIẢI PHÓNG MẶT BẰNG NHANH GỐC
F5: BT_QDGPMBNhanhDChinh
A6: STT | B6: Số QĐ thưởng GPMB nhanh gốc | C6: N/T/N gốc | D6: Số QĐ thưởng GPMB nhanh Đ.Chỉnh | E6: N/T/N Đ.Chỉnh | F6: Id_DM_QDTGPMBNhanhGoc | G6: SoQDThuongGPMBNhanhDC | H6: NTNDieuChinh
A7: 1 | B7: 220 | C7: =IF(B7<>"",INDEX(Table8[N/T/N GPMB nhanh gốc],MATCH(B7,Table8[Số QĐ thưởng GPMB nhanh gốc],0)),"") -> 45361 | D7: 221 | E7: 45366
A8: =A7+1 -> 2 | B8: 230 | C8: =IF(B8<>"",INDEX(Table8[N/T/N GPMB nhanh gốc],MATCH(B8,Table8[Số QĐ thưởng GPMB nhanh gốc],0)),"") -> 45392 | D8: 231 | E8: 45397
A9: =A8+1 -> 3 | B9: 230 | C9: =IF(B9<>"",INDEX(Table8[N/T/N GPMB nhanh gốc],MATCH(B9,Table8[Số QĐ thưởng GPMB nhanh gốc],0)),"") -> 45392 | D9: Tạm ứng | E9: 45402
A10: =A9+1 -> 4 | B10: 230 | C10: =IF(B10<>"",INDEX(Table8[N/T/N GPMB nhanh gốc],MATCH(B10,Table8[Số QĐ thưởng GPMB nhanh gốc],0)),"") -> 45392 | D10: 232 | E10: 45407
A11: =A10+1 -> 5 | B11: 240 | C11: =IF(B11<>"",INDEX(Table8[N/T/N GPMB nhanh gốc],MATCH(B11,Table8[Số QĐ thưởng GPMB nhanh gốc],0)),"") -> 45422 | D11: 241 | E11: 45432
A12: =A11+1 -> 6 | C12: =IF(B12<>"",INDEX(Table8[N/T/N GPMB nhanh gốc],MATCH(B12,Table8[Số QĐ thưởng GPMB nhanh gốc],0)),"")
A13: =A12+1 -> 7 | C13: =IF(B13<>"",INDEX(Table8[N/T/N GPMB nhanh gốc],MATCH(B13,Table8[Số QĐ thưởng GPMB nhanh gốc],0)),"")
A14: =A13+1 -> 8 | C14: =IF(B14<>"",INDEX(Table8[N/T/N GPMB nhanh gốc],MATCH(B14,Table8[Số QĐ thưởng GPMB nhanh gốc],0)),"")
A15: =A14+1 -> 9 | C15: =IF(B15<>"",INDEX(Table8[N/T/N GPMB nhanh gốc],MATCH(B15,Table8[Số QĐ thưởng GPMB nhanh gốc],0)),"")
A16: =A15+1 -> 10 | C16: =IF(B16<>"",INDEX(Table8[N/T/N GPMB nhanh gốc],MATCH(B16,Table8[Số QĐ thưởng GPMB nhanh gốc],0)),"")
A17: =A16+1 -> 11 | C17: =IF(B17<>"",INDEX(Table8[N/T/N GPMB nhanh gốc],MATCH(B17,Table8[Số QĐ thưởng GPMB nhanh gốc],0)),"")
A18: =A17+1 -> 12 | C18: =IF(B18<>"",INDEX(Table8[N/T/N GPMB nhanh gốc],MATCH(B18,Table8[Số QĐ thưởng GPMB nhanh gốc],0)),"")
A19: =A18+1 -> 13 | C19: =IF(B19<>"",INDEX(Table8[N/T/N GPMB nhanh gốc],MATCH(B19,Table8[Số QĐ thưởng GPMB nhanh gốc],0)),"")
A20: =A19+1 -> 14 | C20: =IF(B20<>"",INDEX(Table8[N/T/N GPMB nhanh gốc],MATCH(B20,Table8[Số QĐ thưởng GPMB nhanh gốc],0)),"")
A21: =A20+1 -> 15 | C21: =IF(B21<>"",INDEX(Table8[N/T/N GPMB nhanh gốc],MATCH(B21,Table8[Số QĐ thưởng GPMB nhanh gốc],0)),"")
A22: =A21+1 -> 16 | C22: =IF(B22<>"",INDEX(Table8[N/T/N GPMB nhanh gốc],MATCH(B22,Table8[Số QĐ thưởng GPMB nhanh gốc],0)),"")
A23: =A22+1 -> 17 | C23: =IF(B23<>"",INDEX(Table8[N/T/N GPMB nhanh gốc],MATCH(B23,Table8[Số QĐ thưởng GPMB nhanh gốc],0)),"")
... A28: =A27+1 -> 22 | C28: =IF(B28<>"",INDEX(Table8[N/T/N GPMB nhanh gốc],MATCH(B28,Table8[Số QĐ thưởng GPMB nhanh gốc],0)),"")

Sheet 2.2 QĐ T.Hồi đất Đ.Chỉnh
A1: CÔNG TY CỔ PHẦN XÂY DỰNG ĐỨC ANH
A2: KHU CÔNG NGHIỆP CẨM KHÊ
A4: BẢNG THEO DÕI CÁC QUYẾT ĐỊNH THU HỒI ĐẤT ĐIỀU CHỈNH THEO QUYẾT ĐỊNH GỐC
F5: BT_QDTHoiDatDChinh
A6: STT | B6: Số QĐ thu hồi đất gốc | C6: N/T/N gốc | D6: Số QĐ thu hồi đất Đ.Chỉnh | E6: N/T/N Đ.Chỉnh | F6: Id_DM_QDThuhoiDatGoc | G6: SoQDTHDDieuChinh | H6: NTNDieuChinh
C7: =IF(B7<>"",INDEX(Table7[N/T/N],MATCH(B7,Table7[Số QĐ thu hồi đất gốc],0)),"")
C8: =IF(B8<>"",INDEX(Table7[N/T/N],MATCH(B8,Table7[Số QĐ thu hồi đất gốc],0)),"")
C9: =IF(B9<>"",INDEX(Table7[N/T/N],MATCH(B9,Table7[Số QĐ thu hồi đất gốc],0)),"")
C10: =IF(B10<>"",INDEX(Table7[N/T/N],MATCH(B10,Table7[Số QĐ thu hồi đất gốc],0)),"")
C11: =IF(B11<>"",INDEX(Table7[N/T/N],MATCH(B11,Table7[Số QĐ thu hồi đất gốc],0)),"")
C12: =IF(B12<>"",INDEX(Table7[N/T/N],MATCH(B12,Table7[Số QĐ thu hồi đất gốc],0)),"")
C13: =IF(B13<>"",INDEX(Table7[N/T/N],MATCH(B13,Table7[Số QĐ thu hồi đất gốc],0)),"")
C14: =IF(B14<>"",INDEX(Table7[N/T/N],MATCH(B14,Table7[Số QĐ thu hồi đất gốc],0)),"")
C15: =IF(B15<>"",INDEX(Table7[N/T/N],MATCH(B15,Table7[Số QĐ thu hồi đất gốc],0)),"")
C16: =IF(B16<>"",INDEX(Table7[N/T/N],MATCH(B16,Table7[Số QĐ thu hồi đất gốc],0)),"")

Sheet 3. TH giá trị
A1: CÔNG TY CỔ PHẦN XÂY DỰNG ĐỨC ANH
A2: KHU CÔNG NGHIỆP CẨM KHÊ
A4: Ghi chú: Dữ liệu màu đen nhạt là dữ liệu nhập thủ công; dữ liệu màu đen đậm là dữ liệu được mang từ bảng khác sang; dữ liệu màu đỏ là kết quả phép tính
A5: BẢNG TỔNG HỢP GIÁ TRỊ TOÀN BỘ DỰ ÁN
A7: STT | B7: Nội dung công việc | C7: Năm | D7: Số tiền theo quyết định(VNĐ) | E7: Tổng giá trị đã chi trả theo phê duyệt | F7: Giá trị còn lại phải chi trả theo phê duyệt
A8: Tổng dự án
A9: 1 | B9: Theo phương án bồi thường | C9: Tổng dự án
A10: 2 | B10: Theo thưởng GPMB nhanh | C10: Tổng dự án
A11: 3 | B11: Theo chi phí hội đồng | C11: Tổng dự án
A12: 4 | B12: Chi phí rải thửa, quy chủ | C12: Tổng dự án
A13: 5 | B13: Chi ngoài các quyết định | C13: Tổng dự án
A14: 6 | B14: Kinh phí tái đinh cư | C14: Tổng dự án
A15: 7 | B15: Kinh phí đền bù nghĩa trang | C15: Tổng dự án
A16: 8 | B16: Kinh phíGPMB nhanh nghĩa trang | C16: Tổng dự án
A17: 9 | B17: Kinh phí hội đồng nghĩa trang | C17: Tổng dự án
A18: Tổng năm 2018
A19: 1 | B19: Theo phương án bồi thường | C19: 2018
A20: 2 | B20: Theo thưởng GPMB nhanh | C20: 2018
A21: 3 | B21: Theo chi phí hội đồng | C21: 2018
A22: 4 | B22: Chi phí rải thửa, quy chủ | C22: 2018
A23: 5 | B23: Chi ngoài các quyết định | C23: 2018
A24: 6 | B24: Kinh phí tái đinh cư | C24: 2018
A25: 7 | B25: Kinh phí đền bù nghĩa trang | C25: 2018
A26: 8 | B26: Kinh phíGPMB nhanh nghĩa trang | C26: 2018
A27: 9 | B27: Kinh phí hội đồng nghĩa trang | C27: 2018

Sheet 4. C.Tiết P.Án B.Thường
A1: CÔNG TY CỔ PHẦN XÂY DỰNG ĐỨC ANH
A2: KHU CÔNG NGHIỆP CẨM KHÊ
A4: BẢNG CHI TIẾT BỒI THƯỜNG, GIẢI PHÓNG MẶT BẰNG NHANH CỦA ĐỐI TƯỢNG THEO QUYẾT ĐỊNH BỒI THƯỜNG + GIẢI PHÓNG MẶT BẰNG NHANH GỐC VÀ ĐIỀU CHỈNH
B6: Thông tin QĐ phương án bồi thường | F6: Thông tin QĐ thưởng GPMB nhanh | J6: Thông tin chủ hộ | N6: Giá trị theo quyết định | Q6: Thông tin diện tích
A7: STT | B7: Số QĐ bồi thường gốc | C7: N/T/N QĐ bồi thường gốc | D7: Số QĐ bồi thường điều chỉnh | E7: N/T/N QĐ bồi thường điều chỉnh | F7: Số QĐ thưởng GPMB nhanh gốc | G7: N/T/N QĐ GPMB nhanh gốc | H7: Số QĐ thưởng GPMB nhanh điều chỉnh | I7: N/T/N QĐ GPMB nhanh điều chỉnh | J7: Họ và tên chủ hộ | K7: Xã/phường | L7: Khu/thôn | M7: CMT/CCCD | N7: Bồi thưởng giải phóng mặt bằng | O7: Thưởng giải phóng mặt bằng nhanh | P7: Tổng giá trị | Q7: Tổng diện tích thu hồi | R7: LUC | S7: LUK | T7: BHK | U7: NTS | V7: RSX | W7: ONT | X7: CLN | Y7: CLN (vườn) | Z7: BCS | AA7: DTL | AB7: DGT | AC7: DCS | AD7: NTD | AE7: MNC
A8: Ghi chú | B8: Lấy Id trong DM | D8: lấy id trong sheet 2. theo cột Tạm Ứng | F8: Id trong sheet 1. theo cột Tạm Ứng | H8: Id trong sheett 2.1 theo cột Tạm Ứng | J8: BT_ThongTinChuHo
A9: BT_CTietPAnBThuong | B9: Id_DM_QDBoiThuongGoc | D9: Id_QDPABTDChinh | F9: Id_QDPABTKHopGPMBNhanh | H9: Id_QDGPMBNhanhDChinh | J9: HoVaTenChuHo | K9: XaPhuong | L9: KhuThon | M9: CCCD | N9: BTGPMB | O9: ThuongGPMBNhanh | P9: TongGiaTri | Q9: TongDTThuHoi | R9: LUC | S9: LUK | T9: BHK | U9: NTS | V9: RSX | W9: ONT | X9: CLN | Y9: CLNV | Z9: BCS | AA9: DTL | AB9: DGT | AC9: DCS | AD9: NTD | AE9: MNC
A10: Tổng | N10: =SUBTOTAL(9,N11:N19954) -> 4500000000 | O10: =SUBTOTAL(9,O11:O19954) -> 440000000 | P10: =SUBTOTAL(9,P11:P19954) -> 4940000000 | Q10: =SUBTOTAL(9,Q11:Q19954) -> 0 | R10: =SUBTOTAL(9,R11:R19954) -> 0 | S10: =SUBTOTAL(9,S11:S19954) -> 0 | T10: =SUBTOTAL(9,T11:T19954) -> 0 | U10: =SUBTOTAL(9,U11:U19954) -> 0 | ... AE10: =SUBTOTAL(9,AE11:AE19954) -> 0
A11: 1 | B11: Tạm ứng | C11: =IF(B11<>"",INDEX(Table6[N/T/N PABT gốc],MATCH(B11,Table6[Số QĐ bồi thường gốc],0)),"") -> 0 | E11: {=IF(D11<>"",INDEX('2. QĐ PABT Đ.Chỉnh'!$E$7:$E$19989,MATCH(B11&D11,'2. QĐ PABT Đ.Chỉnh'!$B$7:$B$19989&'2. QĐ PABT Đ.Chỉnh'!$D$7:$D$19989,0)),"")} | G11: {=IF(F11="","",IF(OR(B11="Tạm ứng",B11=""),"",INDEX('1. QĐ PABT K.hợp GPMB nhanh'!$E$7:$E$20000,MATCH(B11&F11,'1. QĐ PABT K.hợp GPMB nhanh'!$B$7:$B$20000&'1. QĐ PABT K.hợp GPMB nhanh'!$D$7:$D$20000,0))))} | I11: {=IF(H11="","",IF(OR(F11="Tạm ứng",F11=""),"",INDEX('2.1 QĐ GPMB nhanh Đ.Chỉnh'!$E$7:$E$19999,MATCH(F11&H11,'2.1 QĐ GPMB nhanh Đ.Chỉnh'!$B$7:$B$19999&'2.1 QĐ GPMB nhanh Đ.Chỉnh'!$D$7:$D$19999,0))))} | J11: Nguyễn Đức Anh | K11: Tiên Cát | L11: Minh Hà | M11: 123A | N11: 100000000 | O11: 0 | P11: =N11+O11 -> 100000000 | Q11: =SUM(R11:XFD11) -> 0 | Z11: 0 | AA11: 0 | AB11: 0 | AC11: 0 | AD11: 0 | AE11: 0
A12: 2 | B12: 120 | C12: =IF(B12<>"",INDEX(Table6[N/T/N PABT gốc],MATCH(B12,Table6[Số QĐ bồi thường gốc],0)),"") -> 45356 | E12: {=IF(D12<>"",INDEX('2. QĐ PABT Đ.Chỉnh'!$E$7:$E$19989,MATCH(B12&D12,'2. QĐ PABT Đ.Chỉnh'!$B$7:$B$19989&'2. QĐ PABT Đ.Chỉnh'!$D$7:$D$19989,0)),"")} | G12: {=IF(F12="","",IF(OR(B12="Tạm ứng",B12=""),"",INDEX('1. QĐ PABT K.hợp GPMB nhanh'!$E$7:$E$20000,MATCH(B12&F12,'1. QĐ PABT K.hợp GPMB nhanh'!$B$7:$B$20000&'1. QĐ PABT K.hợp GPMB nhanh'!$D$7:$D$20000,0))))} | I12: {=IF(H12="","",IF(OR(F12="Tạm ứng",F12=""),"",INDEX('2.1 QĐ GPMB nhanh Đ.Chỉnh'!$E$7:$E$19999,MATCH(F12&H12,'2.1 QĐ GPMB nhanh Đ.Chỉnh'!$B$7:$B$19999&'2.1 QĐ GPMB nhanh Đ.Chỉnh'!$D$7:$D$19999,0))))} | J12: Nguyễn Đức Anh | K12: Tiên Cát | L12: Minh Hà | M12: 123A | N12: 200000000 | O12: 0 | P12: =N12+O12 -> 200000000 | Q12: =SUM(R12:XFD12) -> 0 | Z12: 0 | AA12: 0 | AB12: 0 | AC12: 0 | AD12: 0 | AE12: 0
A13: 3 | B13: 110 | C13: =IF(B13<>"",INDEX(Table6[N/T/N PABT gốc],MATCH(B13,Table6[Số QĐ bồi thường gốc],0)),"") -> 45327 | D13: Tạm ứng | E13: {=IF(D13<>"",INDEX('2. QĐ PABT Đ.Chỉnh'!$E$7:$E$19989,MATCH(B13&D13,'2. QĐ PABT Đ.Chỉnh'!$B$7:$B$19989&'2. QĐ PABT Đ.Chỉnh'!$D$7:$D$19989,0)),"")} -> 0 | G13: {=IF(F13="","",IF(OR(B13="Tạm ứng",B13=""),"",INDEX('1. QĐ PABT K.hợp GPMB nhanh'!$E$7:$E$20000,MATCH(B13&F13,'1. QĐ PABT K.hợp GPMB nhanh'!$B$7:$B$20000&'1. QĐ PABT K.hợp GPMB nhanh'!$D$7:$D$20000,0))))} | I13: {=IF(H13="","",IF(OR(F13="Tạm ứng",F13=""),"",INDEX('2.1 QĐ GPMB nhanh Đ.Chỉnh'!$E$7:$E$19999,MATCH(F13&H13,'2.1 QĐ GPMB nhanh Đ.Chỉnh'!$B$7:$B$19999&'2.1 QĐ GPMB nhanh Đ.Chỉnh'!$D$7:$D$19999,0))))} | J13: Nguyễn Đức Anh | K13: Tiên Cát | L13: Minh Hà | M13: 123A | N13: 300000000 | O13: 0 | P13: =N13+O13 -> 300000000 | Q13: =SUM(R13:XFD13) -> 0 | Z13: 0 | AA13: 0 | AB13: 0 | AC13: 0 | AD13: 0 | AE13: 0
A14: 4 | B14: 120 | C14: =IF(B14<>"",INDEX(Table6[N/T/N PABT gốc],MATCH(B14,Table6[Số QĐ bồi thường gốc],0)),"") -> 45356 | E14: {=IF(D14<>"",INDEX('2. QĐ PABT Đ.Chỉnh'!$E$7:$E$19989,MATCH(B14&D14,'2. QĐ PABT Đ.Chỉnh'!$B$7:$B$19989&'2. QĐ PABT Đ.Chỉnh'!$D$7:$D$19989,0)),"")} | G14: {=IF(F14="","",IF(OR(B14="Tạm ứng",B14=""),"",INDEX('1. QĐ PABT K.hợp GPMB nhanh'!$E$7:$E$20000,MATCH(B14&F14,'1. QĐ PABT K.hợp GPMB nhanh'!$B$7:$B$20000&'1. QĐ PABT K.hợp GPMB nhanh'!$D$7:$D$20000,0))))} | I14: {=IF(H14="","",IF(OR(F14="Tạm ứng",F14=""),"",INDEX('2.1 QĐ GPMB nhanh Đ.Chỉnh'!$E$7:$E$19999,MATCH(F14&H14,'2.1 QĐ GPMB nhanh Đ.Chỉnh'!$B$7:$B$19999&'2.1 QĐ GPMB nhanh Đ.Chỉnh'!$D$7:$D$19999,0))))} | J14: Nguyễn Đức Anh | K14: Tiên Cát | L14: Minh Hà | M14: 123A | N14: 400000000 | O14: 0 | P14: =N14+O14 -> 400000000 | Q14: =SUM(R14:XFD14) -> 0 | Z14: 0 | AA14: 0 | AB14: 0 | AC14: 0 | AD14: 0 | AE14: 0
A15: 5 | B15: 120 | C15: =IF(B15<>"",INDEX(Table6[N/T/N PABT gốc],MATCH(B15,Table6[Số QĐ bồi thường gốc],0)),"") -> 45356 | D15: 121 | E15: {=IF(D15<>"",INDEX('2. QĐ PABT Đ.Chỉnh'!$E$7:$E$19989,MATCH(B15&D15,'2. QĐ PABT Đ.Chỉnh'!$B$7:$B$19989&'2. QĐ PABT Đ.Chỉnh'!$D$7:$D$19989,0)),"")} -> 45361 | G15: {=IF(F15="","",IF(OR(B15="Tạm ứng",B15=""),"",INDEX('1. QĐ PABT K.hợp GPMB nhanh'!$E$7:$E$20000,MATCH(B15&F15,'1. QĐ PABT K.hợp GPMB nhanh'!$B$7:$B$20000&'1. QĐ PABT K.hợp GPMB nhanh'!$D$7:$D$20000,0))))} | I15: {=IF(H15="","",IF(OR(F15="Tạm ứng",F15=""),"",INDEX('2.1 QĐ GPMB nhanh Đ.Chỉnh'!$E$7:$E$19999,MATCH(F15&H15,'2.1 QĐ GPMB nhanh Đ.Chỉnh'!$B$7:$B$19999&'2.1 QĐ GPMB nhanh Đ.Chỉnh'!$D$7:$D$19999,0))))} | J15: Nguyễn Đức Anh | K15: Tiên Cát | L15: Minh Hà | M15: 123A | N15: 500000000 | O15: 0 | P15: =N15+O15 -> 500000000 | Q15: =SUM(R15:XFD15) -> 0 | Z15: 0 | AA15: 0 | AB15: 0 | AC15: 0 | AD15: 0 | AE15: 0
A16: 6 | B16: 130 | C16: =IF(B16<>"",INDEX(Table6[N/T/N PABT gốc],MATCH(B16,Table6[Số QĐ bồi thường gốc],0)),"") -> 45387 | E16: {=IF(D16<>"",INDEX('2. QĐ PABT Đ.Chỉnh'!$E$7:$E$19989,MATCH(B16&D16,'2. QĐ PABT Đ.Chỉnh'!$B$7:$B$19989&'2. QĐ PABT Đ.Chỉnh'!$D$7:$D$19989,0)),"")} | G16: {=IF(F16="","",IF(OR(B16="Tạm ứng",B16=""),"",INDEX('1. QĐ PABT K.hợp GPMB nhanh'!$E$7:$E$20000,MATCH(B16&F16,'1. QĐ PABT K.hợp GPMB nhanh'!$B$7:$B$20000&'1. QĐ PABT K.hợp GPMB nhanh'!$D$7:$D$20000,0))))} | I16: {=IF(H16="","",IF(OR(F16="Tạm ứng",F16=""),"",INDEX('2.1 QĐ GPMB nhanh Đ.Chỉnh'!$E$7:$E$19999,MATCH(F16&H16,'2.1 QĐ GPMB nhanh Đ.Chỉnh'!$B$7:$B$19999&'2.1 QĐ GPMB nhanh Đ.Chỉnh'!$D$7:$D$19999,0))))} | J16: Nguyễn Đức Anh | K16: Tiên Cát | L16: Minh Hà | M16: 123A | N16: 600000000 | O16: 0 | P16: =N16+O16 -> 600000000 | Q16: =SUM(R16:XFD16) -> 0
A17: 7 | B17: 130 | C17: =IF(B17<>"",INDEX(Table6[N/T/N PABT gốc],MATCH(B17,Table6[Số QĐ bồi thường gốc],0)),"") -> 45387 | D17: 131 | E17: {=IF(D17<>"",INDEX('2. QĐ PABT Đ.Chỉnh'!$E$7:$E$19989,MATCH(B17&D17,'2. QĐ PABT Đ.Chỉnh'!$B$7:$B$19989&'2. QĐ PABT Đ.Chỉnh'!$D$7:$D$19989,0)),"")} -> 45392 | G17: {=IF(F17="","",IF(OR(B17="Tạm ứng",B17=""),"",INDEX('1. QĐ PABT K.hợp GPMB nhanh'!$E$7:$E$20000,MATCH(B17&F17,'1. QĐ PABT K.hợp GPMB nhanh'!$B$7:$B$20000&'1. QĐ PABT K.hợp GPMB nhanh'!$D$7:$D$20000,0))))} | I17: {=IF(H17="","",IF(OR(F17="Tạm ứng",F17=""),"",INDEX('2.1 QĐ GPMB nhanh Đ.Chỉnh'!$E$7:$E$19999,MATCH(F17&H17,'2.1 QĐ GPMB nhanh Đ.Chỉnh'!$B$7:$B$19999&'2.1 QĐ GPMB nhanh Đ.Chỉnh'!$D$7:$D$19999,0))))} | J17: Nguyễn Đức Anh | K17: Tiên Cát | L17: Minh Hà | M17: 123A | N17: 700000000 | O17: 0 | P17: =N17+O17 -> 700000000 | Q17: =SUM(R17:XFD17) -> 0
A18: 8 | B18: 130 | C18: =IF(B18<>"",INDEX(Table6[N/T/N PABT gốc],MATCH(B18,Table6[Số QĐ bồi thường gốc],0)),"") -> 45387 | D18: 132 | E18: {=IF(D18<>"",INDEX('2. QĐ PABT Đ.Chỉnh'!$E$7:$E$19989,MATCH(B18&D18,'2. QĐ PABT Đ.Chỉnh'!$B$7:$B$19989&'2. QĐ PABT Đ.Chỉnh'!$D$7:$D$19989,0)),"")} -> 45397 | G18: {=IF(F18="","",IF(OR(B18="Tạm ứng",B18=""),"",INDEX('1. QĐ PABT K.hợp GPMB nhanh'!$E$7:$E$20000,MATCH(B18&F18,'1. QĐ PABT K.hợp GPMB nhanh'!$B$7:$B$20000&'1. QĐ PABT K.hợp GPMB nhanh'!$D$7:$D$20000,0))))} | I18: {=IF(H18="","",IF(OR(F18="Tạm ứng",F18=""),"",INDEX('2.1 QĐ GPMB nhanh Đ.Chỉnh'!$E$7:$E$19999,MATCH(F18&H18,'2.1 QĐ GPMB nhanh Đ.Chỉnh'!$B$7:$B$19999&'2.1 QĐ GPMB nhanh Đ.Chỉnh'!$D$7:$D$19999,0))))} | J18: Nguyễn Đức Anh | K18: Tiên Cát | L18: Minh Hà | M18: 123A | N18: 800000000 | O18: 0 | P18: =N18+O18 -> 800000000 | Q18: =SUM(R18:XFD18) -> 0
A19: 9 | B19: 110 | C19: =IF(B19<>"",INDEX(Table6[N/T/N PABT gốc],MATCH(B19,Table6[Số QĐ bồi thường gốc],0)),"") -> 45327 | E19: {=IF(D19<>"",INDEX('2. QĐ PABT Đ.Chỉnh'!$E$7:$E$19989,MATCH(B19&D19,'2. QĐ PABT Đ.Chỉnh'!$B$7:$B$19989&'2. QĐ PABT Đ.Chỉnh'!$D$7:$D$19989,0)),"")} | F19: Tạm ứng | G19: {=IF(F19="","",IF(OR(B19="Tạm ứng",B19=""),"",INDEX('1. QĐ PABT K.hợp GPMB nhanh'!$E$7:$E$20000,MATCH(B19&F19,'1. QĐ PABT K.hợp GPMB nhanh'!$B$7:$B$20000&'1. QĐ PABT K.hợp GPMB nhanh'!$D$7:$D$20000,0))))} -> 0 | I19: {=IF(H19="","",IF(OR(F19="Tạm ứng",F19=""),"",INDEX('2.1 QĐ GPMB nhanh Đ.Chỉnh'!$E$7:$E$19999,MATCH(F19&H19,'2.1 QĐ GPMB nhanh Đ.Chỉnh'!$B$7:$B$19999&'2.1 QĐ GPMB nhanh Đ.Chỉnh'!$D$7:$D$19999,0))))} | J19: Nguyễn Đức Anh | K19: Tiên Cát | L19: Minh Hà | M19: 123A | N19: 0 | O19: 50000000 | P19: =N19+O19 -> 50000000 | Q19: =SUM(R19:XFD19) -> 0
A20: 10 | B20: 120 | C20: =IF(B20<>"",INDEX(Table6[N/T/N PABT gốc],MATCH(B20,Table6[Số QĐ bồi thường gốc],0)),"") -> 45356 | E20: {=IF(D20<>"",INDEX('2. QĐ PABT Đ.Chỉnh'!$E$7:$E$19989,MATCH(B20&D20,'2. QĐ PABT Đ.Chỉnh'!$B$7:$B$19989&'2. QĐ PABT Đ.Chỉnh'!$D$7:$D$19989,0)),"")} | F20: 220 | G20: {=IF(F20="","",IF(OR(B20="Tạm ứng",B20=""),"",INDEX('1. QĐ PABT K.hợp GPMB nhanh'!$E$7:$E$20000,MATCH(B20&F20,'1. QĐ PABT K.hợp GPMB nhanh'!$B$7:$B$20000&'1. QĐ PABT K.hợp GPMB nhanh'!$D$7:$D$20000,0))))} -> 45361 | I20: {=IF(H20="","",IF(OR(F20="Tạm ứng",F20=""),"",INDEX('2.1 QĐ GPMB nhanh Đ.Chỉnh'!$E$7:$E$19999,MATCH(F20&H20,'2.1 QĐ GPMB nhanh Đ.Chỉnh'!$B$7:$B$19999&'2.1 QĐ GPMB nhanh Đ.Chỉnh'!$D$7:$D$19999,0))))} | J20: Nguyễn Đức Anh | K20: Tiên Cát | L20: Minh Hà | M20: 123A | N20: 0 | O20: 40000000 | P20: =N20+O20 -> 40000000 | Q20: =SUM(R20:XFD20) -> 0 | Z20: 0 | AA20: 0 | AB20: 0 | AC20: 0 | AD20: 0 | AE20: 0
A21: 11 | B21: 120 | C21: =IF(B21<>"",INDEX(Table6[N/T/N PABT gốc],MATCH(B21,Table6[Số QĐ bồi thường gốc],0)),"") -> 45356 | D21: 121 | E21: {=IF(D21<>"",INDEX('2. QĐ PABT Đ.Chỉnh'!$E$7:$E$19989,MATCH(B21&D21,'2. QĐ PABT Đ.Chỉnh'!$B$7:$B$19989&'2. QĐ PABT Đ.Chỉnh'!$D$7:$D$19989,0)),"")} -> 45361 | F21: 220 | G21: {=IF(F21="","",IF(OR(B21="Tạm ứng",B21=""),"",INDEX('1. QĐ PABT K.hợp GPMB nhanh'!$E$7:$E$20000,MATCH(B21&F21,'1. QĐ PABT K.hợp GPMB nhanh'!$B$7:$B$20000&'1. QĐ PABT K.hợp GPMB nhanh'!$D$7:$D$20000,0))))} -> 45361 | H21: 221 | I21: {=IF(H21="","",IF(OR(F21="Tạm ứng",F21=""),"",INDEX('2.1 QĐ GPMB nhanh Đ.Chỉnh'!$E$7:$E$19999,MATCH(F21&H21,'2.1 QĐ GPMB nhanh Đ.Chỉnh'!$B$7:$B$19999&'2.1 QĐ GPMB nhanh Đ.Chỉnh'!$D$7:$D$19999,0))))} -> 45366 | J21: Nguyễn Đức Anh | K21: Tiên Cát | L21: Minh Hà | M21: 123A | N21: 0 | O21: 50000000 | P21: =N21+O21 -> 50000000 | Q21: =SUM(R21:XFD21) -> 0 | Z21: 0 | AA21: 0 | AB21: 0 | AC21: 0 | AD21: 0 | AE21: 0
A22: 12 | B22: 130 | C22: =IF(B22<>"",INDEX(Table6[N/T/N PABT gốc],MATCH(B22,Table6[Số QĐ bồi thường gốc],0)),"") -> 45387 | E22: {=IF(D22<>"",INDEX('2. QĐ PABT Đ.Chỉnh'!$E$7:$E$19989,MATCH(B22&D22,'2. QĐ PABT Đ.Chỉnh'!$B$7:$B$19989&'2. QĐ PABT Đ.Chỉnh'!$D$7:$D$19989,0)),"")} | F22: 230 | G22: {=IF(F22="","",IF(OR(B22="Tạm ứng",B22=""),"",INDEX('1. QĐ PABT K.hợp GPMB nhanh'!$E$7:$E$20000,MATCH(B22&F22,'1. QĐ PABT K.hợp GPMB nhanh'!$B$7:$B$20000&'1. QĐ PABT K.hợp GPMB nhanh'!$D$7:$D$20000,0))))} -> 45392 | I22: {=IF(H22="","",IF(OR(F22="Tạm ứng",F22=""),"",INDEX('2.1 QĐ GPMB nhanh Đ.Chỉnh'!$E$7:$E$19999,MATCH(F22&H22,'2.1 QĐ GPMB nhanh Đ.Chỉnh'!$B$7:$B$19999&'2.1 QĐ GPMB nhanh Đ.Chỉnh'!$D$7:$D$19999,0))))} | J22: Nguyễn Đức Anh | K22: Tiên Cát | L22: Minh Hà | M22: 123A | N22: 0 | O22: 60000000 | P22: =N22+O22 -> 60000000 | Q22: =SUM(R22:XFD22) -> 0 | Z22: 0 | AA22: 0 | AB22: 0 | AC22: 0 | AD22: 0 | AE22: 0
A23: 13 | B23: 130 | C23: =IF(B23<>"",INDEX(Table6[N/T/N PABT gốc],MATCH(B23,Table6[Số QĐ bồi thường gốc],0)),"") -> 45387 | D23: 131 | E23: {=IF(D23<>"",INDEX('2. QĐ PABT Đ.Chỉnh'!$E$7:$E$19989,MATCH(B23&D23,'2. QĐ PABT Đ.Chỉnh'!$B$7:$B$19989&'2. QĐ PABT Đ.Chỉnh'!$D$7:$D$19989,0)),"")} -> 45392 | F23: 230 | G23: {=IF(F23="","",IF(OR(B23="Tạm ứng",B23=""),"",INDEX('1. QĐ PABT K.hợp GPMB nhanh'!$E$7:$E$20000,MATCH(B23&F23,'1. QĐ PABT K.hợp GPMB nhanh'!$B$7:$B$20000&'1. QĐ PABT K.hợp GPMB nhanh'!$D$7:$D$20000,0))))} -> 45392 | H23: 231 | I23: {=IF(H23="","",IF(OR(F23="Tạm ứng",F23=""),"",INDEX('2.1 QĐ GPMB nhanh Đ.Chỉnh'!$E$7:$E$19999,MATCH(F23&H23,'2.1 QĐ GPMB nhanh Đ.Chỉnh'!$B$7:$B$19999&'2.1 QĐ GPMB nhanh Đ.Chỉnh'!$D$7:$D$19999,0))))} -> 45397 | J23: Nguyễn Đức Anh | K23: Tiên Cát | L23: Minh Hà | M23: 123A | N23: 0 | O23: 70000000 | P23: =N23+O23 -> 70000000 | Q23: =SUM(R23:XFD23) -> 0 | Z23: 0 | AA23: 0 | AB23: 0 | AC23: 0 | AD23: 0 | AE23: 0
A24: 14 | B24: 130 | C24: =IF(B24<>"",INDEX(Table6[N/T/N PABT gốc],MATCH(B24,Table6[Số QĐ bồi thường gốc],0)),"") -> 45387 | D24: 132 | E24: {=IF(D24<>"",INDEX('2. QĐ PABT Đ.Chỉnh'!$E$7:$E$19989,MATCH(B24&D24,'2. QĐ PABT Đ.Chỉnh'!$B$7:$B$19989&'2. QĐ PABT Đ.Chỉnh'!$D$7:$D$19989,0)),"")} -> 45397 | F24: 230 | G24: {=IF(F24="","",IF(OR(B24="Tạm ứng",B24=""),"",INDEX('1. QĐ PABT K.hợp GPMB nhanh'!$E$7:$E$20000,MATCH(B24&F24,'1. QĐ PABT K.hợp GPMB nhanh'!$B$7:$B$20000&'1. QĐ PABT K.hợp GPMB nhanh'!$D$7:$D$20000,0))))} -> 45392 | H24: Tạm ứng | I24: {=IF(H24="","",IF(OR(F24="Tạm ứng",F24=""),"",INDEX('2.1 QĐ GPMB nhanh Đ.Chỉnh'!$E$7:$E$19999,MATCH(F24&H24,'2.1 QĐ GPMB nhanh Đ.Chỉnh'!$B$7:$B$19999&'2.1 QĐ GPMB nhanh Đ.Chỉnh'!$D$7:$D$19999,0))))} -> 45402 | J24: Nguyễn Đức Anh | K24: Tiên Cát | L24: Minh Hà | M24: 123A | N24: 0 | O24: 80000000 | P24: =N24+O24 -> 80000000 | Q24: =SUM(R24:XFD24) -> 0 | Z24: 0 | AA24: 0 | AB24: 0 | AC24: 0 | AD24: 0 | AE24: 0
A25: 15 | B25: 140 | C25: =IF(B25<>"",INDEX(Table6[N/T/N PABT gốc],MATCH(B25,Table6[Số QĐ bồi thường gốc],0)),"") -> 45417 | E25: {=IF(D25<>"",INDEX('2. QĐ PABT Đ.Chỉnh'!$E$7:$E$19989,MATCH(B25&D25,'2. QĐ PABT Đ.Chỉnh'!$B$7:$B$19989&'2. QĐ PABT Đ.Chỉnh'!$D$7:$D$19989,0)),"")} | G25: {=IF(F25="","",IF(OR(B25="Tạm ứng",B25=""),"",INDEX('1. QĐ PABT K.hợp GPMB nhanh'!$E$7:$E$20000,MATCH(B25&F25,'1. QĐ PABT K.hợp GPMB nhanh'!$B$7:$B$20000&'1. QĐ PABT K.hợp GPMB nhanh'!$D$7:$D$20000,0))))} | I25: {=IF(H25="","",IF(OR(F25="Tạm ứng",F25=""),"",INDEX('2.1 QĐ GPMB nhanh Đ.Chỉnh'!$E$7:$E$19999,MATCH(F25&H25,'2.1 QĐ GPMB nhanh Đ.Chỉnh'!$B$7:$B$19999&'2.1 QĐ GPMB nhanh Đ.Chỉnh'!$D$7:$D$19999,0))))} | J25: Nguyễn Đức Anh | K25: Tiên Cát | L25: Minh Hà | M25: 123A | N25: 1000000000 | O25: 0 | P25: =N25+O25 -> 1000000000 | Q25: =SUM(R25:XFD25) -> 0 | Z25: 0 | AA25: 0 | AB25: 0 | AC25: 0 | AD25: 0 | AE25: 0
A26: 17 | B26: 140 | C26: =IF(B26<>"",INDEX(Table6[N/T/N PABT gốc],MATCH(B26,Table6[Số QĐ bồi thường gốc],0)),"") -> 45417 | E26: {=IF(D26<>"",INDEX('2. QĐ PABT Đ.Chỉnh'!$E$7:$E$19989,MATCH(B26&D26,'2. QĐ PABT Đ.Chỉnh'!$B$7:$B$19989&'2. QĐ PABT Đ.Chỉnh'!$D$7:$D$19989,0)),"")} | F26: 240 | G26: {=IF(F26="","",IF(OR(B26="Tạm ứng",B26=""),"",INDEX('1. QĐ PABT K.hợp GPMB nhanh'!$E$7:$E$20000,MATCH(B26&F26,'1. QĐ PABT K.hợp GPMB nhanh'!$B$7:$B$20000&'1. QĐ PABT K.hợp GPMB nhanh'!$D$7:$D$20000,0))))} -> 45422 | I26: {=IF(H26="","",IF(OR(F26="Tạm ứng",F26=""),"",INDEX('2.1 QĐ GPMB nhanh Đ.Chỉnh'!$E$7:$E$19999,MATCH(F26&H26,'2.1 QĐ GPMB nhanh Đ.Chỉnh'!$B$7:$B$19999&'2.1 QĐ GPMB nhanh Đ.Chỉnh'!$D$7:$D$19999,0))))} | J26: Nguyễn Đức Anh | K26: Tiên Cát | L26: Minh Hà | M26: 123A | N26: 0 | O26: 100000000 | P26: =N26+O26 -> 100000000 | Q26: =SUM(R26:XFD26) -> 0 | Z26: 0 | AA26: 0 | AB26: 0 | AC26: 0 | AD26: 0 | AE26: 0
A27: 18 | B27: 140 | C27: =IF(B27<>"",INDEX(Table6[N/T/N PABT gốc],MATCH(B27,Table6[Số QĐ bồi thường gốc],0)),"") -> 45417 | D27: 141 | E27: {=IF(D27<>"",INDEX('2. QĐ PABT Đ.Chỉnh'!$E$7:$E$19989,MATCH(B27&D27,'2. QĐ PABT Đ.Chỉnh'!$B$7:$B$19989&'2. QĐ PABT Đ.Chỉnh'!$D$7:$D$19989,0)),"")} -> 45427 | G27: {=IF(F27="","",IF(OR(B27="Tạm ứng",B27=""),"",INDEX('1. QĐ PABT K.hợp GPMB nhanh'!$E$7:$E$20000,MATCH(B27&F27,'1. QĐ PABT K.hợp GPMB nhanh'!$B$7:$B$20000&'1. QĐ PABT K.hợp GPMB nhanh'!$D$7:$D$20000,0))))} | I27: {=IF(H27="","",IF(OR(F27="Tạm ứng",F27=""),"",INDEX('2.1 QĐ GPMB nhanh Đ.Chỉnh'!$E$7:$E$19999,MATCH(F27&H27,'2.1 QĐ GPMB nhanh Đ.Chỉnh'!$B$7:$B$19999&'2.1 QĐ GPMB nhanh Đ.Chỉnh'!$D$7:$D$19999,0))))} | J27: Nguyễn Đức Anh | K27: Tiên Cát | L27: Minh Hà | M27: 123A | N27: -100000000 | O27: 0 | P27: =N27+O27 -> -100000000 | Q27: =SUM(R27:XFD27) -> 0 | Z27: 0 | AA27: 0 | AB27: 0 | AC27: 0 | AD27: 0 | AE27: 0
A28: 19 | B28: 140 | C28: =IF(B28<>"",INDEX(Table6[N/T/N PABT gốc],MATCH(B28,Table6[Số QĐ bồi thường gốc],0)),"") -> 45417 | E28: {=IF(D28<>"",INDEX('2. QĐ PABT Đ.Chỉnh'!$E$7:$E$19989,MATCH(B28&D28,'2. QĐ PABT Đ.Chỉnh'!$B$7:$B$19989&'2. QĐ PABT Đ.Chỉnh'!$D$7:$D$19989,0)),"")} | F28: 240 | G28: {=IF(F28="","",IF(OR(B28="Tạm ứng",B28=""),"",INDEX('1. QĐ PABT K.hợp GPMB nhanh'!$E$7:$E$20000,MATCH(B28&F28,'1. QĐ PABT K.hợp GPMB nhanh'!$B$7:$B$20000&'1. QĐ PABT K.hợp GPMB nhanh'!$D$7:$D$20000,0))))} -> 45422 | H28: 241 | I28: {=IF(H28="","",IF(OR(F28="Tạm ứng",F28=""),"",INDEX('2.1 QĐ GPMB nhanh Đ.Chỉnh'!$E$7:$E$19999,MATCH(F28&H28,'2.1 QĐ GPMB nhanh Đ.Chỉnh'!$B$7:$B$19999&'2.1 QĐ GPMB nhanh Đ.Chỉnh'!$D$7:$D$19999,0))))} -> 45432 | J28: Nguyễn Đức Anh | K28: Tiên Cát | L28: Minh Hà | M28: 123A | N28: 0 | O28: -10000000 | P28: =N28+O28 -> -10000000 | Q28: =SUM(R28:XFD28) -> 0
A29: 20 | C29: =IF(B29<>"",INDEX(Table6[N/T/N PABT gốc],MATCH(B29,Table6[Số QĐ bồi thường gốc],0)),"") | E29: {=IF(D29<>"",INDEX('2. QĐ PABT Đ.Chỉnh'!$E$7:$E$19989,MATCH(B29&D29,'2. QĐ PABT Đ.Chỉnh'!$B$7:$B$19989&'2. QĐ PABT Đ.Chỉnh'!$D$7:$D$19989,0)),"")} | G29: {=IF(F29="","",IF(OR(B29="Tạm ứng",B29=""),"",INDEX('1. QĐ PABT K.hợp GPMB nhanh'!$E$7:$E$20000,MATCH(B29&F29,'1. QĐ PABT K.hợp GPMB nhanh'!$B$7:$B$20000&'1. QĐ PABT K.hợp GPMB nhanh'!$D$7:$D$20000,0))))} | I29: {=IF(H29="","",IF(OR(F29="Tạm ứng",F29=""),"",INDEX('2.1 QĐ GPMB nhanh Đ.Chỉnh'!$E$7:$E$19999,MATCH(F29&H29,'2.1 QĐ GPMB nhanh Đ.Chỉnh'!$B$7:$B$19999&'2.1 QĐ GPMB nhanh Đ.Chỉnh'!$D$7:$D$19999,0))))} | P29: =N29+O29 -> 0 | Q29: =SUM(R29:XFD29) -> 0
A30: 21 | C30: =IF(B30<>"",INDEX(Table6[N/T/N PABT gốc],MATCH(B30,Table6[Số QĐ bồi thường gốc],0)),"") | E30: {=IF(D30<>"",INDEX('2. QĐ PABT Đ.Chỉnh'!$E$7:$E$19989,MATCH(B30&D30,'2. QĐ PABT Đ.Chỉnh'!$B$7:$B$19989&'2. QĐ PABT Đ.Chỉnh'!$D$7:$D$19989,0)),"")} | G30: {=IF(F30="","",IF(OR(B30="Tạm ứng",B30=""),"",INDEX('1. QĐ PABT K.hợp GPMB nhanh'!$E$7:$E$20000,MATCH(B30&F30,'1. QĐ PABT K.hợp GPMB nhanh'!$B$7:$B$20000&'1. QĐ PABT K.hợp GPMB nhanh'!$D$7:$D$20000,0))))} | I30: {=IF(H30="","",IF(OR(F30="Tạm ứng",F30=""),"",INDEX('2.1 QĐ GPMB nhanh Đ.Chỉnh'!$E$7:$E$19999,MATCH(F30&H30,'2.1 QĐ GPMB nhanh Đ.Chỉnh'!$B$7:$B$19999&'2.1 QĐ GPMB nhanh Đ.Chỉnh'!$D$7:$D$19999,0))))} | P30: =N30+O30 -> 0 | Q30: =SUM(R30:XFD30) -> 0
A31: 22 | C31: =IF(B31<>"",INDEX(Table6[N/T/N PABT gốc],MATCH(B31,Table6[Số QĐ bồi thường gốc],0)),"") | E31: {=IF(D31<>"",INDEX('2. QĐ PABT Đ.Chỉnh'!$E$7:$E$19989,MATCH(B31&D31,'2. QĐ PABT Đ.Chỉnh'!$B$7:$B$19989&'2. QĐ PABT Đ.Chỉnh'!$D$7:$D$19989,0)),"")} | G31: {=IF(F31="","",IF(OR(B31="Tạm ứng",B31=""),"",INDEX('1. QĐ PABT K.hợp GPMB nhanh'!$E$7:$E$20000,MATCH(B31&F31,'1. QĐ PABT K.hợp GPMB nhanh'!$B$7:$B$20000&'1. QĐ PABT K.hợp GPMB nhanh'!$D$7:$D$20000,0))))} | I31: {=IF(H31="","",IF(OR(F31="Tạm ứng",F31=""),"",INDEX('2.1 QĐ GPMB nhanh Đ.Chỉnh'!$E$7:$E$19999,MATCH(F31&H31,'2.1 QĐ GPMB nhanh Đ.Chỉnh'!$B$7:$B$19999&'2.1 QĐ GPMB nhanh Đ.Chỉnh'!$D$7:$D$19999,0))))} | P31: =N31+O31 -> 0 | Q31: =SUM(R31:XFD31) -> 0
A32: 23 | C32: =IF(B32<>"",INDEX(Table6[N/T/N PABT gốc],MATCH(B32,Table6[Số QĐ bồi thường gốc],0)),"") | E32: {=IF(D32<>"",INDEX('2. QĐ PABT Đ.Chỉnh'!$E$7:$E$19989,MATCH(B32&D32,'2. QĐ PABT Đ.Chỉnh'!$B$7:$B$19989&'2. QĐ PABT Đ.Chỉnh'!$D$7:$D$19989,0)),"")} | G32: {=IF(F32="","",IF(OR(B32="Tạm ứng",B32=""),"",INDEX('1. QĐ PABT K.hợp GPMB nhanh'!$E$7:$E$20000,MATCH(B32&F32,'1. QĐ PABT K.hợp GPMB nhanh'!$B$7:$B$20000&'1. QĐ PABT K.hợp GPMB nhanh'!$D$7:$D$20000,0))))} | I32: {=IF(H32="","",IF(OR(F32="Tạm ứng",F32=""),"",INDEX('2.1 QĐ GPMB nhanh Đ.Chỉnh'!$E$7:$E$19999,MATCH(F32&H32,'2.1 QĐ GPMB nhanh Đ.Chỉnh'!$B$7:$B$19999&'2.1 QĐ GPMB nhanh Đ.Chỉnh'!$D$7:$D$19999,0))))} | P32: =N32+O32 -> 0 | Q32: =SUM(R32:XFD32) -> 0
A33: 24 | C33: =IF(B33<>"",INDEX(Table6[N/T/N PABT gốc],MATCH(B33,Table6[Số QĐ bồi thường gốc],0)),"") | E33: {=IF(D33<>"",INDEX('2. QĐ PABT Đ.Chỉnh'!$E$7:$E$19989,MATCH(B33&D33,'2. QĐ PABT Đ.Chỉnh'!$B$7:$B$19989&'2. QĐ PABT Đ.Chỉnh'!$D$7:$D$19989,0)),"")} | G33: {=IF(F33="","",IF(OR(B33="Tạm ứng",B33=""),"",INDEX('1. QĐ PABT K.hợp GPMB nhanh'!$E$7:$E$20000,MATCH(B33&F33,'1. QĐ PABT K.hợp GPMB nhanh'!$B$7:$B$20000&'1. QĐ PABT K.hợp GPMB nhanh'!$D$7:$D$20000,0))))} | I33: {=IF(H33="","",IF(OR(F33="Tạm ứng",F33=""),"",INDEX('2.1 QĐ GPMB nhanh Đ.Chỉnh'!$E$7:$E$19999,MATCH(F33&H33,'2.1 QĐ GPMB nhanh Đ.Chỉnh'!$B$7:$B$19999&'2.1 QĐ GPMB nhanh Đ.Chỉnh'!$D$7:$D$19999,0))))} | P33: =N33+O33 -> 0 | Q33: =SUM(R33:XFD33) -> 0

Sheet 4.1 TH P.Án B.Thường
A1: CÔNG TY CỔ PHẦN XÂY DỰNG ĐỨC ANH
A2: KHU CÔNG NGHIỆP CẨM KHÊ
A4: BẢNG TỔNG HỢP GIÁ TRỊ BỒI THƯỞNG, THƯỞNG GIẢI PHÓNG MẶT BẰNG NHANH CỦA ĐỐI TƯỢNG THEO QUYẾT ĐỊNH BỒI THƯỜNG, THƯỞNG GIẢI PHÓNG MẶT BẰNG NHANH GỐC VÀ ĐIỀU CHỈNH
A6: STT | B6: Thông tin QĐ phương án bồi thường | D6: Thông tin QĐ thưởng GPMB nhanh | F6: Thông tin chủ hộ | J6: Thông tin giá trị theo quyết định | M6: Thông tin giá trị đã chi trả | P6: Thông tin giá trị còn lại
B7: Số QĐ bồi thương gốc | C7: N/T/N QĐ bồi thường gốc | D7: Số QĐ GPMB nhanh gốc | E7: N/T/N QĐ GPMB nhanh gốc | F7: Họ và tên chủ hộ | G7: Xã/phường | H7: Khu/thôn | I7: CMT/CCCD | J7: Bồi thưởng giải phóng mặt bằng | K7: Thưởng giải phóng mặt bằng nhanh | L7: Tổng giá trị | M7: Bồi thưởng giải phóng mặt bằng | N7: Thưởng giải phóng mặt bằng nhanh | O7: Tổng giá trị | P7: Bồi thưởng giải phóng mặt bằng | Q7: Thưởng giải phóng mặt bằng nhanh | R7: Tổng giá trị
J8: =SUBTOTAL(9,J9:J28) -> 4100000000 | K8: =SUBTOTAL(9,K9:K28) -> 310000000 | L8: =SUBTOTAL(9,L9:L28) -> 4410000000 | M8: =SUBTOTAL(9,M9:M28) -> 3900000000 | N8: =SUBTOTAL(9,N9:N28) -> 310000000 | O8: =SUBTOTAL(9,O9:O28) -> 4210000000 | P8: =SUBTOTAL(9,P9:P28) -> 200000000 | Q8: =SUBTOTAL(9,Q9:Q28) -> 0 | R8: =SUBTOTAL(9,R9:R28) -> 200000000
A9: 1 | B9: {=_xlfn.UNIQUE(_xlfn.SORTBY(_xlfn.HSTACK(_xlfn._xlws.FILTER('4. C.Tiết P.Án B.Thường'!$B$11:$C$19950,('4. C.Tiết P.Án B.Thường'!$B$11:$B$19950<>"Tạm ứng")*('4. C.Tiết P.Án B.Thường'!$D$11:$D$19950<>"Tạm ứng")*('4. C.Tiết P.Án B.Thường'!$F$11:$F$19950<>"Tạm ứng")*('4. C.Tiết P.Án B.Thường'!$H$11:$H$19950<>"Tạm ứng"),0),_xlfn._xlws.FILTER('4. C.Tiết P.Án B.Thường'!$F$11:$G$19950,('4. C.Tiết P.Án B.Thường'!$B$11:$B$19950<>"Tạm ứng")*('4. C.Tiết P.Án B.Thường'!$D$11:$D$19950<>"Tạm ứng")*('4. C.Tiết P.Án B.Thường'!$F$11:$F$19950<>"Tạm ứng")*('4. C.Tiết P.Án B.Thường'!$H$11:$H$19950<>"Tạm ứng"),0),_xlfn._xlws.FILTER('4. C.Tiết P.Án B.Thường'!$J$11:$M$19950,('4. C.Tiết P.Án B.Thường'!$B$11:$B$19950<>"Tạm ứng")*('4. C.Tiết P.Án B.Thường'!$D$11:$D$19950<>"Tạm ứng")*('4. C.Tiết P.Án B.Thường'!$F$11:$F$19950<>"Tạm ứng")*('4. C.Tiết P.Án B.Thường'!$H$11:$H$19950<>"Tạm ứng"),0)),_xlfn._xlws.FILTER('4. C.Tiết P.Án B.Thường'!$B$11:$B$19950,('4. C.Tiết P.Án B.Thường'!$B$11:$B$19950<>"Tạm ứng")*('4. C.Tiết P.Án B.Thường'!$D$11:$D$19950<>"Tạm ứng")*('4. C.Tiết P.Án B.Thường'!$F$11:$F$19950<>"Tạm ứng")*('4. C.Tiết P.Án B.Thường'!$H$11:$H$19950<>"Tạm ứng"),0),1,_xlfn._xlws.FILTER('4. C.Tiết P.Án B.Thường'!$F$11:$F$19950,('4. C.Tiết P.Án B.Thường'!$B$11:$B$19950<>"Tạm ứng")*('4. C.Tiết P.Án B.Thường'!$D$11:$D$19950<>"Tạm ứng")*('4. C.Tiết P.Án B.Thường'!$F$11:$F$19950<>"Tạm ứng")*('4. C.Tiết P.Án B.Thường'!$H$11:$H$19950<>"Tạm ứng"),0),1))} -> 120 | C9: 45356 | D9: 220 | E9: 45361 | F9: Nguyễn Đức Anh | G9: Tiên Cát | H9: Minh Hà | I9: 123A | J9: =SUMIFS('4. C.Tiết P.Án B.Thường'!$N$11:$N$20001,'4. C.Tiết P.Án B.Thường'!$J$11:$J$20001,'4.1 TH P.Án B.Thường'!$F9,'4. C.Tiết P.Án B.Thường'!$K$11:$K$20001,'4.1 TH P.Án B.Thường'!$G9,'4. C.Tiết P.Án B.Thường'!$L$11:$L$20001,'4.1 TH P.Án B.Thường'!$H9,'4. C.Tiết P.Án B.Thường'!$M$11:$M$20001,'4.1 TH P.Án B.Thường'!$I9,'4. C.Tiết P.Án B.Thường'!$B$11:$B$20001,'4.1 TH P.Án B.Thường'!$B9,'4. C.Tiết P.Án B.Thường'!$D$11:$D$20001,"<>"&"tạm ứng",'4. C.Tiết P.Án B.Thường'!$F$11:$F$20001,IF('4.1 TH P.Án B.Thường'!$D9=0,"",'4.1 TH P.Án B.Thường'!$D9)) -> 0 | K9: =SUMIFS('4. C.Tiết P.Án B.Thường'!$O$11:$O$20001,'4. C.Tiết P.Án B.Thường'!$J$11:$J$20001,'4.1 TH P.Án B.Thường'!$F9,'4. C.Tiết P.Án B.Thường'!$K$11:$K$20001,'4.1 TH P.Án B.Thường'!$G9,'4. C.Tiết P.Án B.Thường'!$L$11:$L$20001,'4.1 TH P.Án B.Thường'!$H9,'4. C.Tiết P.Án B.Thường'!$M$11:$M$20001,'4.1 TH P.Án B.Thường'!$I9,'4. C.Tiết P.Án B.Thường'!$B$11:$B$20001,'4.1 TH P.Án B.Thường'!$B9,'4. C.Tiết P.Án B.Thường'!$F$11:$F$20001,'4.1 TH P.Án B.Thường'!$D9,'4. C.Tiết P.Án B.Thường'!$F$11:$F$20001,"<>"&"Tạm ứng",'4. C.Tiết P.Án B.Thường'!$H$11:$H$20001,"<>"&"Tạm ứng") -> 90000000 | L9: =J9+K9 -> 90000000 | M9: =(SUMIFS('9. Thu, chi PABT'!$T$11:$T$20001,'9. Thu, chi PABT'!$J$11:$J$20001,'4.1 TH P.Án B.Thường'!$F9,'9. Thu, chi PABT'!$K$11:$K$20001,'4.1 TH P.Án B.Thường'!$G9,'9. Thu, chi PABT'!$L$11:$L$20001,'4.1 TH P.Án B.Thường'!$H9,'9. Thu, chi PABT'!$M$11:$M$20001,'4.1 TH P.Án B.Thường'!$I9,'9. Thu, chi PABT'!$B$11:$B$20001,'4.1 TH P.Án B.Thường'!$B9,'9. Thu, chi PABT'!$D$11:$D$20001,"<>"&"Tạm ứng",'9. Thu, chi PABT'!$F$11:$F$20001,IF('4.1 TH P.Án B.Thường'!$D9=0,"",'4.1 TH P.Án B.Thường'!$D9),'9. Thu, chi PABT'!$H$11:$H$20001,"<>"&"Tạm ứng")-SUMIFS('9. Thu, chi PABT'!$T$11:$T$20001,'9. Thu, chi PABT'!$J$11:$J$20001,'4.1 TH P.Án B.Thường'!$F9,'9. Thu, chi PABT'!$K$11:$K$20001,'4.1 TH P.Án B.Thường'!$G9,'9. Thu, chi PABT'!$L$11:$L$20001,'4.1 TH P.Án B.Thường'!$H9,'9. Thu, chi PABT'!$M$11:$M$20001,'4.1 TH P.Án B.Thường'!$I9,'9. Thu, chi PABT'!$B$11:$B$20001,'4.1 TH P.Án B.Thường'!$B9,'9. Thu, chi PABT'!$F$11:$F$20001,'4.1 TH P.Án B.Thường'!$D9,'9. Thu, chi PABT'!$F$11:$F$20001,"<>"&"Tạm ứng",'9. Thu, chi PABT'!$H$11:$H$20001,"<>"&"Tạm ứng"))-(SUMIFS('9. Thu, chi PABT'!$U$11:$U$20001,'9. Thu, chi PABT'!$J$11:$J$20001,'4.1 TH P.Án B.Thường'!$F9,'9. Thu, chi PABT'!$K$11:$K$20001,'4.1 TH P.Án B.Thường'!$G9,'9. Thu, chi PABT'!$L$11:$L$20001,'4.1 TH P.Án B.Thường'!$H9,'9. Thu, chi PABT'!$M$11:$M$20001,'4.1 TH P.Án B.Thường'!$I9,'9. Thu, chi PABT'!$B$11:$B$20001,'4.1 TH P.Án B.Thường'!$B9,'9. Thu, chi PABT'!$F$11:$F$20001,IF('4.1 TH P.Án B.Thường'!$D9=0,"",'4.1 TH P.Án B.Thường'!$D9))-SUMIFS('9. Thu, chi PABT'!$U$11:$U$20001,'9. Thu, chi PABT'!$J$11:$J$20001,'4.1 TH P.Án B.Thường'!$F9,'9. Thu, chi PABT'!$K$11:$K$20001,'4.1 TH P.Án B.Thường'!$G9,'9. Thu, chi PABT'!$L$11:$L$20001,'4.1 TH P.Án B.Thường'!$H9,'9. Thu, chi PABT'!$M$11:$M$20001,'4.1 TH P.Án B.Thường'!$I9,'9. Thu, chi PABT'!$B$11:$B$20001,'4.1 TH P.Án B.Thường'!$B9,'9. Thu, chi PABT'!$F$11:$F$20001,'4.1 TH P.Án B.Thường'!$D9)) -> 0 | N9: =SUMIFS('9. Thu, chi PABT'!$T$11:$T$20001,'9. Thu, chi PABT'!$J$11:$J$20001,'4.1 TH P.Án B.Thường'!$F9,'9. Thu, chi PABT'!$K$11:$K$20001,'4.1 TH P.Án B.Thường'!$G9,'9. Thu, chi PABT'!$L$11:$L$20001,'4.1 TH P.Án B.Thường'!$H9,'9. Thu, chi PABT'!$M$11:$M$20001,'4.1 TH P.Án B.Thường'!$I9,'9. Thu, chi PABT'!$B$11:$B$20001,'4.1 TH P.Án B.Thường'!$B9,'9. Thu, chi PABT'!$F$11:$F$20001,'4.1 TH P.Án B.Thường'!$D9,'9. Thu, chi PABT'!$F$11:$F$20001,"<>"&"Tạm ứng",'9. Thu, chi PABT'!$H$11:$H$20001,"<>"&"Tạm ứng")-SUMIFS('9. Thu, chi PABT'!$U$11:$U$20001,'9. Thu, chi PABT'!$J$11:$J$20001,'4.1 TH P.Án B.Thường'!$F9,'9. Thu, chi PABT'!$K$11:$K$20001,'4.1 TH P.Án B.Thường'!$G9,'9. Thu, chi PABT'!$L$11:$L$20001,'4.1 TH P.Án B.Thường'!$H9,'9. Thu, chi PABT'!$M$11:$M$20001,'4.1 TH P.Án B.Thường'!$I9,'9. Thu, chi PABT'!$B$11:$B$20001,'4.1 TH P.Án B.Thường'!$B9,'9. Thu, chi PABT'!$F$11:$F$20001,'4.1 TH P.Án B.Thường'!$D9) -> 90000000 | O9: =M9+N9 -> 90000000 | P9: =J9-M9 -> 0 | Q9: =K9-N9 -> 0 | R9: =L9-O9 -> 0
A10: 2 | B10: 120 | C10: 45356 | D10: 0 | F10: Nguyễn Đức Anh | G10: Tiên Cát | H10: Minh Hà | I10: 123A | J10: =SUMIFS('4. C.Tiết P.Án B.Thường'!$N$11:$N$20001,'4. C.Tiết P.Án B.Thường'!$J$11:$J$20001,'4.1 TH P.Án B.Thường'!$F10,'4. C.Tiết P.Án B.Thường'!$K$11:$K$20001,'4.1 TH P.Án B.Thường'!$G10,'4. C.Tiết P.Án B.Thường'!$L$11:$L$20001,'4.1 TH P.Án B.Thường'!$H10,'4. C.Tiết P.Án B.Thường'!$M$11:$M$20001,'4.1 TH P.Án B.Thường'!$I10,'4. C.Tiết P.Án B.Thường'!$B$11:$B$20001,'4.1 TH P.Án B.Thường'!$B10,'4. C.Tiết P.Án B.Thường'!$D$11:$D$20001,"<>"&"tạm ứng",'4. C.Tiết P.Án B.Thường'!$F$11:$F$20001,IF('4.1 TH P.Án B.Thường'!$D10=0,"",'4.1 TH P.Án B.Thường'!$D10)) -> 1100000000 | K10: =SUMIFS('4. C.Tiết P.Án B.Thường'!$O$11:$O$20001,'4. C.Tiết P.Án B.Thường'!$J$11:$J$20001,'4.1 TH P.Án B.Thường'!$F10,'4. C.Tiết P.Án B.Thường'!$K$11:$K$20001,'4.1 TH P.Án B.Thường'!$G10,'4. C.Tiết P.Án B.Thường'!$L$11:$L$20001,'4.1 TH P.Án B.Thường'!$H10,'4. C.Tiết P.Án B.Thường'!$M$11:$M$20001,'4.1 TH P.Án B.Thường'!$I10,'4. C.Tiết P.Án B.Thường'!$B$11:$B$20001,'4.1 TH P.Án B.Thường'!$B10,'4. C.Tiết P.Án B.Thường'!$F$11:$F$20001,'4.1 TH P.Án B.Thường'!$D10,'4. C.Tiết P.Án B.Thường'!$F$11:$F$20001,"<>"&"Tạm ứng",'4. C.Tiết P.Án B.Thường'!$H$11:$H$20001,"<>"&"Tạm ứng") -> 0 | L10: =J10+K10 -> 1100000000 | M10: =(SUMIFS('9. Thu, chi PABT'!$T$11:$T$20001,'9. Thu, chi PABT'!$J$11:$J$20001,'4.1 TH P.Án B.Thường'!$F10,'9. Thu, chi PABT'!$K$11:$K$20001,'4.1 TH P.Án B.Thường'!$G10,'9. Thu, chi PABT'!$L$11:$L$20001,'4.1 TH P.Án B.Thường'!$H10,'9. Thu, chi PABT'!$M$11:$M$20001,'4.1 TH P.Án B.Thường'!$I10,'9. Thu, chi PABT'!$B$11:$B$20001,'4.1 TH P.Án B.Thường'!$B10,'9. Thu, chi PABT'!$D$11:$D$20001,"<>"&"Tạm ứng",'9. Thu, chi PABT'!$F$11:$F$20001,IF('4.1 TH P.Án B.Thường'!$D10=0,"",'4.1 TH P.Án B.Thường'!$D10),'9. Thu, chi PABT'!$H$11:$H$20001,"<>"&"Tạm ứng")-SUMIFS('9. Thu, chi PABT'!$T$11:$T$20001,'9. Thu, chi PABT'!$J$11:$J$20001,'4.1 TH P.Án B.Thường'!$F10,'9. Thu, chi PABT'!$K$11:$K$20001,'4.1 TH P.Án B.Thường'!$G10,'9. Thu, chi PABT'!$L$11:$L$20001,'4.1 TH P.Án B.Thường'!$H10,'9. Thu, chi PABT'!$M$11:$M$20001,'4.1 TH P.Án B.Thường'!$I10,'9. Thu, chi PABT'!$B$11:$B$20001,'4.1 TH P.Án B.Thường'!$B10,'9. Thu, chi PABT'!$F$11:$F$20001,'4.1 TH P.Án B.Thường'!$D10,'9. Thu, chi PABT'!$F$11:$F$20001,"<>"&"Tạm ứng",'9. Thu, chi PABT'!$H$11:$H$20001,"<>"&"Tạm ứng"))-(SUMIFS('9. Thu, chi PABT'!$U$11:$U$20001,'9. Thu, chi PABT'!$J$11:$J$20001,'4.1 TH P.Án B.Thường'!$F10,'9. Thu, chi PABT'!$K$11:$K$20001,'4.1 TH P.Án B.Thường'!$G10,'9. Thu, chi PABT'!$L$11:$L$20001,'4.1 TH P.Án B.Thường'!$H10,'9. Thu, chi PABT'!$M$11:$M$20001,'4.1 TH P.Án B.Thường'!$I10,'9. Thu, chi PABT'!$B$11:$B$20001,'4.1 TH P.Án B.Thường'!$B10,'9. Thu, chi PABT'!$F$11:$F$20001,IF('4.1 TH P.Án B.Thường'!$D10=0,"",'4.1 TH P.Án B.Thường'!$D10))-SUMIFS('9. Thu, chi PABT'!$U$11:$U$20001,'9. Thu, chi PABT'!$J$11:$J$20001,'4.1 TH P.Án B.Thường'!$F10,'9. Thu, chi PABT'!$K$11:$K$20001,'4.1 TH P.Án B.Thường'!$G10,'9. Thu, chi PABT'!$L$11:$L$20001,'4.1 TH P.Án B.Thường'!$H10,'9. Thu, chi PABT'!$M$11:$M$20001,'4.1 TH P.Án B.Thường'!$I10,'9. Thu, chi PABT'!$B$11:$B$20001,'4.1 TH P.Án B.Thường'!$B10,'9. Thu, chi PABT'!$F$11:$F$20001,'4.1 TH P.Án B.Thường'!$D10)) -> 900000000 | N10: =SUMIFS('9. Thu, chi PABT'!$T$11:$T$20001,'9. Thu, chi PABT'!$J$11:$J$20001,'4.1 TH P.Án B.Thường'!$F10,'9. Thu, chi PABT'!$K$11:$K$20001,'4.1 TH P.Án B.Thường'!$G10,'9. Thu, chi PABT'!$L$11:$L$20001,'4.1 TH P.Án B.Thường'!$H10,'9. Thu, chi PABT'!$M$11:$M$20001,'4.1 TH P.Án B.Thường'!$I10,'9. Thu, chi PABT'!$B$11:$B$20001,'4.1 TH P.Án B.Thường'!$B10,'9. Thu, chi PABT'!$F$11:$F$20001,'4.1 TH P.Án B.Thường'!$D10,'9. Thu, chi PABT'!$F$11:$F$20001,"<>"&"Tạm ứng",'9. Thu, chi PABT'!$H$11:$H$20001,"<>"&"Tạm ứng")-SUMIFS('9. Thu, chi PABT'!$U$11:$U$20001,'9. Thu, chi PABT'!$J$11:$J$20001,'4.1 TH P.Án B.Thường'!$F10,'9. Thu, chi PABT'!$K$11:$K$20001,'4.1 TH P.Án B.Thường'!$G10,'9. Thu, chi PABT'!$L$11:$L$20001,'4.1 TH P.Án B.Thường'!$H10,'9. Thu, chi PABT'!$M$11:$M$20001,'4.1 TH P.Án B.Thường'!$I10,'9. Thu, chi PABT'!$B$11:$B$20001,'4.1 TH P.Án B.Thường'!$B10,'9. Thu, chi PABT'!$F$11:$F$20001,'4.1 TH P.Án B.Thường'!$D10) -> 0 | O10: =M10+N10 -> 900000000 | P10: =J10-M10 -> 200000000 | Q10: =K10-N10 -> 0 | R10: =L10-O10 -> 200000000
A11: 3 | B11: 130 | C11: 45387 | D11: 230 | E11: 45392 | F11: Nguyễn Đức Anh | G11: Tiên Cát | H11: Minh Hà | I11: 123A | J11: =SUMIFS('4. C.Tiết P.Án B.Thường'!$N$11:$N$20001,'4. C.Tiết P.Án B.Thường'!$J$11:$J$20001,'4.1 TH P.Án B.Thường'!$F11,'4. C.Tiết P.Án B.Thường'!$K$11:$K$20001,'4.1 TH P.Án B.Thường'!$G11,'4. C.Tiết P.Án B.Thường'!$L$11:$L$20001,'4.1 TH P.Án B.Thường'!$H11,'4. C.Tiết P.Án B.Thường'!$M$11:$M$20001,'4.1 TH P.Án B.Thường'!$I11,'4. C.Tiết P.Án B.Thường'!$B$11:$B$20001,'4.1 TH P.Án B.Thường'!$B11,'4. C.Tiết P.Án B.Thường'!$D$11:$D$20001,"<>"&"tạm ứng",'4. C.Tiết P.Án B.Thường'!$F$11:$F$20001,IF('4.1 TH P.Án B.Thường'!$D11=0,"",'4.1 TH P.Án B.Thường'!$D11)) -> 0 | K11: =SUMIFS('4. C.Tiết P.Án B.Thường'!$O$11:$O$20001,'4. C.Tiết P.Án B.Thường'!$J$11:$J$20001,'4.1 TH P.Án B.Thường'!$F11,'4. C.Tiết P.Án B.Thường'!$K$11:$K$20001,'4.1 TH P.Án B.Thường'!$G11,'4. C.Tiết P.Án B.Thường'!$L$11:$L$20001,'4.1 TH P.Án B.Thường'!$H11,'4. C.Tiết P.Án B.Thường'!$M$11:$M$20001,'4.1 TH P.Án B.Thường'!$I11,'4. C.Tiết P.Án B.Thường'!$B$11:$B$20001,'4.1 TH P.Án B.Thường'!$B11,'4. C.Tiết P.Án B.Thường'!$F$11:$F$20001,'4.1 TH P.Án B.Thường'!$D11,'4. C.Tiết P.Án B.Thường'!$F$11:$F$20001,"<>"&"Tạm ứng",'4. C.Tiết P.Án B.Thường'!$H$11:$H$20001,"<>"&"Tạm ứng") -> 130000000 | L11: =J11+K11 -> 130000000 | M11: =(SUMIFS('9. Thu, chi PABT'!$T$11:$T$20001,'9. Thu, chi PABT'!$J$11:$J$20001,'4.1 TH P.Án B.Thường'!$F11,'9. Thu, chi PABT'!$K$11:$K$20001,'4.1 TH P.Án B.Thường'!$G11,'9. Thu, chi PABT'!$L$11:$L$20001,'4.1 TH P.Án B.Thường'!$H11,'9. Thu, chi PABT'!$M$11:$M$20001,'4.1 TH P.Án B.Thường'!$I11,'9. Thu, chi PABT'!$B$11:$B$20001,'4.1 TH P.Án B.Thường'!$B11,'9. Thu, chi PABT'!$D$11:$D$20001,"<>"&"Tạm ứng",'9. Thu, chi PABT'!$F$11:$F$20001,IF('4.1 TH P.Án B.Thường'!$D11=0,"",'4.1 TH P.Án B.Thường'!$D11),'9. Thu, chi PABT'!$H$11:$H$20001,"<>"&"Tạm ứng")-SUMIFS('9. Thu, chi PABT'!$T$11:$T$20001,'9. Thu, chi PABT'!$J$11:$J$20001,'4.1 TH P.Án B.Thường'!$F11,'9. Thu, chi PABT'!$K$11:$K$20001,'4.1 TH P.Án B.Thường'!$G11,'9. Thu, chi PABT'!$L$11:$L$20001,'4.1 TH P.Án B.Thường'!$H11,'9. Thu, chi PABT'!$M$11:$M$20001,'4.1 TH P.Án B.Thường'!$I11,'9. Thu, chi PABT'!$B$11:$B$20001,'4.1 TH P.Án B.Thường'!$B11,'9. Thu, chi PABT'!$F$11:$F$20001,'4.1 TH P.Án B.Thường'!$D11,'9. Thu, chi PABT'!$F$11:$F$20001,"<>"&"Tạm ứng",'9. Thu, chi PABT'!$H$11:$H$20001,"<>"&"Tạm ứng"))-(SUMIFS('9. Thu, chi PABT'!$U$11:$U$20001,'9. Thu, chi PABT'!$J$11:$J$20001,'4.1 TH P.Án B.Thường'!$F11,'9. Thu, chi PABT'!$K$11:$K$20001,'4.1 TH P.Án B.Thường'!$G11,'9. Thu, chi PABT'!$L$11:$L$20001,'4.1 TH P.Án B.Thường'!$H11,'9. Thu, chi PABT'!$M$11:$M$20001,'4.1 TH P.Án B.Thường'!$I11,'9. Thu, chi PABT'!$B$11:$B$20001,'4.1 TH P.Án B.Thường'!$B11,'9. Thu, chi PABT'!$F$11:$F$20001,IF('4.1 TH P.Án B.Thường'!$D11=0,"",'4.1 TH P.Án B.Thường'!$D11))-SUMIFS('9. Thu, chi PABT'!$U$11:$U$20001,'9. Thu, chi PABT'!$J$11:$J$20001,'4.1 TH P.Án B.Thường'!$F11,'9. Thu, chi PABT'!$K$11:$K$20001,'4.1 TH P.Án B.Thường'!$G11,'9. Thu, chi PABT'!$L$11:$L$20001,'4.1 TH P.Án B.Thường'!$H11,'9. Thu, chi PABT'!$M$11:$M$20001,'4.1 TH P.Án B.Thường'!$I11,'9. Thu, chi PABT'!$B$11:$B$20001,'4.1 TH P.Án B.Thường'!$B11,'9. Thu, chi PABT'!$F$11:$F$20001,'4.1 TH P.Án B.Thường'!$D11)) -> 0 | N11: =SUMIFS('9. Thu, chi PABT'!$T$11:$T$20001,'9. Thu, chi PABT'!$J$11:$J$20001,'4.1 TH P.Án B.Thường'!$F11,'9. Thu, chi PABT'!$K$11:$K$20001,'4.1 TH P.Án B.Thường'!$G11,'9. Thu, chi PABT'!$L$11:$L$20001,'4.1 TH P.Án B.Thường'!$H11,'9. Thu, chi PABT'!$M$11:$M$20001,'4.1 TH P.Án B.Thường'!$I11,'9. Thu, chi PABT'!$B$11:$B$20001,'4.1 TH P.Án B.Thường'!$B11,'9. Thu, chi PABT'!$F$11:$F$20001,'4.1 TH P.Án B.Thường'!$D11,'9. Thu, chi PABT'!$F$11:$F$20001,"<>"&"Tạm ứng",'9. Thu, chi PABT'!$H$11:$H$20001,"<>"&"Tạm ứng")-SUMIFS('9. Thu, chi PABT'!$U$11:$U$20001,'9. Thu, chi PABT'!$J$11:$J$20001,'4.1 TH P.Án B.Thường'!$F11,'9. Thu, chi PABT'!$K$11:$K$20001,'4.1 TH P.Án B.Thường'!$G11,'9. Thu, chi PABT'!$L$11:$L$20001,'4.1 TH P.Án B.Thường'!$H11,'9. Thu, chi PABT'!$M$11:$M$20001,'4.1 TH P.Án B.Thường'!$I11,'9. Thu, chi PABT'!$B$11:$B$20001,'4.1 TH P.Án B.Thường'!$B11,'9. Thu, chi PABT'!$F$11:$F$20001,'4.1 TH P.Án B.Thường'!$D11) -> 130000000 | O11: =M11+N11 -> 130000000 | P11: =J11-M11 -> 0 | Q11: =K11-N11 -> 0 | R11: =L11-O11 -> 0
